Workbook

Sheet 00 Dashboard
A1: TheEduAssist SEO Operations Dashboard
A2: Professional team workspace | Canonical site: https://www.theeduassist.com/ | Update task and performance tabs, not this dashboard.
A4: Work Queue | E4: Performance Snapshot | I4: This Week's Operating Rules
A5: Open tasks | B5: =COUNTIFS('01 Task Board'!$A$5:$A$304,"<>",'01 Task Board'!$J$5:$J$304,"<>Done") -> 14 | E5: Latest organic traffic | F5: =IFERROR(LOOKUP(2,1/('05 Performance'!$A$5:$A$104<>""),'05 Performance'!$B$5:$B$104),0) -> 3900 | I5: 1 | J5: Every task must have an owner, due date and evidence link.
A6: Critical open tasks | B6: =COUNTIFS('01 Task Board'!$A$5:$A$304,"<>",'01 Task Board'!$H$5:$H$304,"Critical",'01 Task Board'!$J$5:$J$304,"<>Done") -> 4 | E6: Latest organic keywords | F6: =IFERROR(LOOKUP(2,1/('05 Performance'!$A$5:$A$104<>""),'05 Performance'!$C$5:$C$104),0) -> 201 | I6: 2 | J6: Use www.theeduassist.com URLs in all active tabs.
A7: Overdue tasks | B7: =COUNTIFS('01 Task Board'!$A$5:$A$304,"<>",'01 Task Board'!$R$5:$R$304,"Overdue") -> 14 | E7: Latest authority score | F7: =IFERROR(LOOKUP(2,1/('05 Performance'!$A$5:$A$104<>""),'05 Performance'!$D$5:$D$104),0) -> 8 | I7: 3 | J7: Do not create or chase irrelevant backlinks just because authority is high.
A8: Open technical issues | B8: =COUNTIFS('04 Technical Issues'!$A$5:$A$204,"<>",'04 Technical Issues'!$K$5:$K$204,"<>Resolved") -> 9 | E8: Latest referring domains | F8: =IFERROR(LOOKUP(2,1/('05 Performance'!$A$5:$A$104<>""),'05 Performance'!$E$5:$E$104),0) -> 0 | I8: 4 | J8: Track clicks, impressions, leads and conversions, not rankings alone.
A9: Content items published | B9: =COUNTIFS('03 Content Pipeline'!$A$5:$A$204,"<>",'03 Content Pipeline'!$J$5:$J$204,"Published") -> 6 | E9: Latest GSC clicks | F9: =IFERROR(LOOKUP(2,1/('05 Performance'!$A$5:$A$104<>""),'05 Performance'!$L$5:$L$104),0) -> 0 | I9: 5 | J9: Mark old workbook findings as Needs Revalidation before acting.
E10: Latest organic leads | F10: =IFERROR(LOOKUP(2,1/('05 Performance'!$A$5:$A$104<>""),'05 Performance'!$Q$5:$Q$104),0) -> 0 | I10: 6 | J10: AR/VR legacy ideas are archived and excluded from the active SEO plan.
E11: Latest conversion rate | F11: =IFERROR(LOOKUP(2,1/('05 Performance'!$A$5:$A$104<>""),'05 Performance'!$R$5:$R$104),0) -> 0
A13: Priority Focus
A14: Priority | B14: Workstream | C14: Action | D14: Why it matters | E14: Owner | F14: Due | G14: Status | H14: Evidence | I14: QA | J14: Expected result | K14: Impact | L14: Notes
A15: P1 | B15: Technical | C15: Validate www canonical, redirect chain and sitemap URLs | D15: Prevents duplicate/canonical confusion | E15: Developer | G15: Not Started | I15: SEO Manager | J15: Only canonical URLs index | K15: High
A16: P1 | B16: Technical | C16: Revalidate legacy 404 case-study URLs and homepage links | D16: Removes broken user journeys and crawl waste | E16: Developer | G16: Not Started | I16: QA | J16: No broken featured-project links | K16: High
A17: P1 | B17: Content | C17: Map each important service page to one primary keyword | D17: Stops keyword cannibalization and speeds briefs | E17: SEO Manager | G17: Not Started | I17: Content Lead | J17: Clear keyword-to-page ownership | K17: High
A18: P2 | B18: Reporting | C18: Add GSC and GA4 leads/conversions to weekly reporting | D18: Connects SEO activity to business outcomes | E18: SEO Manager | G18: Not Started | I18: Management | J18: Lead-focused SEO decisions | K18: High

Sheet 01 Task Board
A1: SEO Daily Task Board
A2: One source of truth for daily work. Add every SEO action here, attach evidence, then send it through QA.
A4: Task ID | B4: Date Added | C4: Due Date | D4: Frequency | E4: Workstream | F4: Task | G4: Page / URL | H4: Priority | I4: Owner | J4: Status | K4: Dependency / Blocker | L4: Evidence / Work Link | M4: Result / Notes | N4: QA Owner | O4: QA Status | P4: Completed Date | Q4: Days Open | R4: SLA
A5: SEO-001 | B5: 46230 | C5: 46232 | D5: One-time | E5: Technical SEO | F5: Validate canonical, redirect and sitemap consistency for www domain | G5: https://www.theeduassist.com/ | H5: Critical | I5: Developer | J5: Not Started | N5: SEO Manager | O5: Not Reviewed | Q5: =IF(B5="","",IF(J5="Done",IF(P5="","",P5-B5),TODAY()-B5)) -> 62 | R5: =IF(B5="","",IF(J5="Done","Closed",IF(C5="","No due date",IF(C5<TODAY(),"Overdue",IF(C5-TODAY()<=2,"Due soon","On track"))))) -> Overdue
A6: SEO-002 | B6: 46230 | C6: 46233 | D6: One-time | E6: Technical SEO | F6: Revalidate legacy 404 case-study URLs and remove any broken homepage links | G6: https://www.theeduassist.com/ | H6: Critical | I6: Developer | J6: Not Started | N6: QA | O6: Not Reviewed | Q6: =IF(B6="","",IF(J6="Done",IF(P6="","",P6-B6),TODAY()-B6)) -> 62 | R6: =IF(B6="","",IF(J6="Done","Closed",IF(C6="","No due date",IF(C6<TODAY(),"Overdue",IF(C6-TODAY()<=2,"Due soon","On track"))))) -> Overdue
A7: SEO-003 | B7: 46230 | C7: 46234 | D7: One-time | E7: On-page SEO | F7: Review Contact page H1, title, meta, Organization/ContactPage schema, internal links and conversion tracking | G7: https://www.theeduassist.com/contact/ | H7: High | I7: SEO Manager | J7: Not Started | N7: QA | O7: Not Reviewed | Q7: =IF(B7="","",IF(J7="Done",IF(P7="","",P7-B7),TODAY()-B7)) -> 62 | R7: =IF(B7="","",IF(J7="Done","Closed",IF(C7="","No due date",IF(C7<TODAY(),"Overdue",IF(C7-TODAY()<=2,"Due soon","On track"))))) -> Overdue
A8: SEO-004 | B8: 46230 | C8: 46235 | D8: One-time | E8: On-page SEO | F8: Review About page for company story, team proof, credentials, internal links and CTA | G8: https://www.theeduassist.com/about/ | H8: High | I8: Content Lead | J8: Not Started | N8: SEO Manager | O8: Not Reviewed | Q8: =IF(B8="","",IF(J8="Done",IF(P8="","",P8-B8),TODAY()-B8)) -> 62 | R8: =IF(B8="","",IF(J8="Done","Closed",IF(C8="","No due date",IF(C8<TODAY(),"Overdue",IF(C8-TODAY()<=2,"Due soon","On track"))))) -> Overdue
A9: SEO-005 | B9: 46230 | C9: 46236 | D9: Weekly | E9: Search Console | F9: Export query and page data; flag high-impression low-CTR opportunities | G9: https://search.google.com/search-console/ | H9: High | I9: SEO Manager | J9: Not Started | N9: Management | O9: Not Reviewed | Q9: =IF(B9="","",IF(J9="Done",IF(P9="","",P9-B9),TODAY()-B9)) -> 62 | R9: =IF(B9="","",IF(J9="Done","Closed",IF(C9="","No due date",IF(C9<TODAY(),"Overdue",IF(C9-TODAY()<=2,"Due soon","On track"))))) -> Overdue
A10: SEO-006 | B10: 46230 | C10: 46236 | D10: Weekly | E10: Content SEO | F10: Map unmapped primary keywords to service or pillar pages | G10: See 02 Keyword Map | H10: High | I10: SEO Manager | J10: Not Started | N10: Content Lead | O10: Not Reviewed | Q10: =IF(B10="","",IF(J10="Done",IF(P10="","",P10-B10),TODAY()-B10)) -> 62 | R10: =IF(B10="","",IF(J10="Done","Closed",IF(C10="","No due date",IF(C10<TODAY(),"Overdue",IF(C10-TODAY()<=2,"Due soon","On track"))))) -> Overdue
A11: SEO-007 | B11: 46230 | C11: 46237 | D11: Weekly | E11: Internal Linking | F11: Add contextual links from new/updated articles to relevant service and case-study pages | G11: See 03 Content Pipeline | H11: Medium | I11: Content Writer | J11: Not Started | N11: SEO Manager | O11: Not Reviewed | Q11: =IF(B11="","",IF(J11="Done",IF(P11="","",P11-B11),TODAY()-B11)) -> 62 | R11: =IF(B11="","",IF(J11="Done","Closed",IF(C11="","No due date",IF(C11<TODAY(),"Overdue",IF(C11-TODAY()<=2,"Due soon","On track"))))) -> Overdue
A12: SEO-008 | B12: 46230 | C12: 46237 | D12: Weekly | E12: Technical SEO | F12: Review coverage/indexing, Core Web Vitals and enhancement reports | G12: Search Console / PageSpeed | H12: High | I12: SEO Manager | J12: Not Started | N12: Developer | O12: Not Reviewed | Q12: =IF(B12="","",IF(J12="Done",IF(P12="","",P12-B12),TODAY()-B12)) -> 62 | R12: =IF(B12="","",IF(J12="Done","Closed",IF(C12="","No due date",IF(C12<TODAY(),"Overdue",IF(C12-TODAY()<=2,"Due soon","On track"))))) -> Overdue
A13: SEO-009 | B13: 46230 | C13: 46238 | D13: Weekly | E13: AI Visibility | F13: Check priority questions in Google AI features, ChatGPT, Gemini and Perplexity | G13: See 08 AI Visibility | H13: Medium | I13: SEO Manager | J13: Not Started | N13: Content Lead | O13: Not Reviewed | Q13: =IF(B13="","",IF(J13="Done",IF(P13="","",P13-B13),TODAY()-B13)) -> 62 | R13: =IF(B13="","",IF(J13="Done","Closed",IF(C13="","No due date",IF(C13<TODAY(),"Overdue",IF(C13-TODAY()<=2,"Due soon","On track"))))) -> Overdue
A14: SEO-010 | B14: 46230 | C14: 46238 | D14: Weekly | E14: Backlinks | F14: Qualify 20 relevant link opportunities; reject irrelevant/high-risk domains | G14: See 07 Link Opportunities | H14: Medium | I14: Outreach | J14: Not Started | N14: SEO Manager | O14: Not Reviewed | Q14: =IF(B14="","",IF(J14="Done",IF(P14="","",P14-B14),TODAY()-B14)) -> 62 | R14: =IF(B14="","",IF(J14="Done","Closed",IF(C14="","No due date",IF(C14<TODAY(),"Overdue",IF(C14-TODAY()<=2,"Due soon","On track"))))) -> Overdue
A15: SEO-011 | B15: 46230 | C15: 46239 | D15: Monthly | E15: Reporting | F15: Update organic traffic, keywords, GSC metrics, leads, conversion rate and CWV | G15: See 05 Performance | H15: Critical | I15: SEO Manager | J15: Not Started | N15: Management | O15: Not Reviewed | Q15: =IF(B15="","",IF(J15="Done",IF(P15="","",P15-B15),TODAY()-B15)) -> 62 | R15: =IF(B15="","",IF(J15="Done","Closed",IF(C15="","No due date",IF(C15<TODAY(),"Overdue",IF(C15-TODAY()<=2,"Due soon","On track"))))) -> Overdue
A16: SEO-012 | B16: 46230 | C16: 46239 | D16: One-time | E16: Content Governance | F16: Remove AR/VR items from active content and keyword planning; retain only in archive | G16: See raw archive tabs | H16: High | I16: SEO Manager | J16: Done | L16: Workbook redesign | M16: Deprecated scope removed | N16: Management | O16: Approved | P16: 46230 | Q16: =IF(B16="","",IF(J16="Done",IF(P16="","",P16-B16),TODAY()-B16)) -> 0 | R16: =IF(B16="","",IF(J16="Done","Closed",IF(C16="","No due date",IF(C16<TODAY(),"Overdue",IF(C16-TODAY()<=2,"Due soon","On track"))))) -> Closed
A17: SEO-013 | B17: 46230 | C17: 46240 | D17: One-time | E17: Backlinks | F17: Clean existing backlink list into relevant, realistic and policy-safe opportunities | G17: See 07 Link Opportunities | H17: High | I17: Outreach | J17: In Progress | N17: SEO Manager | O17: Not Reviewed | Q17: =IF(B17="","",IF(J17="Done",IF(P17="","",P17-B17),TODAY()-B17)) -> 62 | R17: =IF(B17="","",IF(J17="Done","Closed",IF(C17="","No due date",IF(C17<TODAY(),"Overdue",IF(C17-TODAY()<=2,"Due soon","On track"))))) -> Overdue
A18: SEO-014 | B18: 46230 | C18: 46240 | D18: One-time | E18: Analytics | F18: Confirm GA4 key events for review form, contact form and consultation/RFP submissions | G18: GA4 | H18: Critical | I18: Developer | J18: Not Started | N18: SEO Manager | O18: Not Reviewed | Q18: =IF(B18="","",IF(J18="Done",IF(P18="","",P18-B18),TODAY()-B18)) -> 62 | R18: =IF(B18="","",IF(J18="Done","Closed",IF(C18="","No due date",IF(C18<TODAY(),"Overdue",IF(C18-TODAY()<=2,"Due soon","On track"))))) -> Overdue
A19: SEO-015 | B19: 46230 | C19: 46241 | D19: One-time | E19: Schema | F19: Validate Organization, Service, Article, Breadcrumb and applicable FAQ markup | G19: Rich Results Test | H19: High | I19: Developer | J19: Not Started | N19: SEO Manager | O19: Not Reviewed | Q19: =IF(B19="","",IF(J19="Done",IF(P19="","",P19-B19),TODAY()-B19)) -> 62 | R19: =IF(B19="","",IF(J19="Done","Closed",IF(C19="","No due date",IF(C19<TODAY(),"Overdue",IF(C19-TODAY()<=2,"Due soon","On track"))))) -> Overdue
Q20: =IF(B20="","",IF(J20="Done",IF(P20="","",P20-B20),TODAY()-B20)) | R20: =IF(B20="","",IF(J20="Done","Closed",IF(C20="","No due date",IF(C20<TODAY(),"Overdue",IF(C20-TODAY()<=2,"Due soon","On track")))))
Q21: =IF(B21="","",IF(J21="Done",IF(P21="","",P21-B21),TODAY()-B21)) | R21: =IF(B21="","",IF(J21="Done","Closed",IF(C21="","No due date",IF(C21<TODAY(),"Overdue",IF(C21-TODAY()<=2,"Due soon","On track")))))
Q22: =IF(B22="","",IF(J22="Done",IF(P22="","",P22-B22),TODAY()-B22)) | R22: =IF(B22="","",IF(J22="Done","Closed",IF(C22="","No due date",IF(C22<TODAY(),"Overdue",IF(C22-TODAY()<=2,"Due soon","On track")))))
Q23: =IF(B23="","",IF(J23="Done",IF(P23="","",P23-B23),TODAY()-B23)) | R23: =IF(B23="","",IF(J23="Done","Closed",IF(C23="","No due date",IF(C23<TODAY(),"Overdue",IF(C23-TODAY()<=2,"Due soon","On track")))))
Q24: =IF(B24="","",IF(J24="Done",IF(P24="","",P24-B24),TODAY()-B24)) | R24: =IF(B24="","",IF(J24="Done","Closed",IF(C24="","No due date",IF(C24<TODAY(),"Overdue",IF(C24-TODAY()<=2,"Due soon","On track")))))
Q25: =IF(B25="","",IF(J25="Done",IF(P25="","",P25-B25),TODAY()-B25)) | R25: =IF(B25="","",IF(J25="Done","Closed",IF(C25="","No due date",IF(C25<TODAY(),"Overdue",IF(C25-TODAY()<=2,"Due soon","On track")))))
Q26: =IF(B26="","",IF(J26="Done",IF(P26="","",P26-B26),TODAY()-B26)) | R26: =IF(B26="","",IF(J26="Done","Closed",IF(C26="","No due date",IF(C26<TODAY(),"Overdue",IF(C26-TODAY()<=2,"Due soon","On track")))))
Q27: =IF(B27="","",IF(J27="Done",IF(P27="","",P27-B27),TODAY()-B27)) | R27: =IF(B27="","",IF(J27="Done","Closed",IF(C27="","No due date",IF(C27<TODAY(),"Overdue",IF(C27-TODAY()<=2,"Due soon","On track")))))
Q28: =IF(B28="","",IF(J28="Done",IF(P28="","",P28-B28),TODAY()-B28)) | R28: =IF(B28="","",IF(J28="Done","Closed",IF(C28="","No due date",IF(C28<TODAY(),"Overdue",IF(C28-TODAY()<=2,"Due soon","On track")))))
Q29: =IF(B29="","",IF(J29="Done",IF(P29="","",P29-B29),TODAY()-B29)) | R29: =IF(B29="","",IF(J29="Done","Closed",IF(C29="","No due date",IF(C29<TODAY(),"Overdue",IF(C29-TODAY()<=2,"Due soon","On track")))))
Q30: =IF(B30="","",IF(J30="Done",IF(P30="","",P30-B30),TODAY()-B30)) | R30: =IF(B30="","",IF(J30="Done","Closed",IF(C30="","No due date",IF(C30<TODAY(),"Overdue",IF(C30-TODAY()<=2,"Due soon","On track")))))
Q31: =IF(B31="","",IF(J31="Done",IF(P31="","",P31-B31),TODAY()-B31)) | R31: =IF(B31="","",IF(J31="Done","Closed",IF(C31="","No due date",IF(C31<TODAY(),"Overdue",IF(C31-TODAY()<=2,"Due soon","On track")))))
... Q304: =IF(B304="","",IF(J304="Done",IF(P304="","",P304-B304),TODAY()-B304)) | R304: =IF(B304="","",IF(J304="Done","Closed",IF(C304="","No due date",IF(C304<TODAY(),"Overdue",IF(C304-TODAY()<=2,"Due soon","On track")))))

Sheet 02 Keyword Map
A1: Keyword-to-Page Map
A2: Use one primary keyword per page, group close variants, and avoid assigning the same intent to multiple pages.
A4: Keyword ID | B4: Keyword | C4: Local Volume | D4: Global Volume | E4: KD | F4: Intent | G4: Cluster / Service | H4: Target Page | I4: Page Type | J4: Keyword Role | K4: Current URL | L4: Mapping Status | M4: Owner | N4: Opportunity Score | O4: Suggested Title / Brief | P4: Meta Description | Q4: Source | R4: Last Reviewed | S4: Next Action | T4: Notes
A5: KW-001 | B5: designing an online course | C5: 90 | D5: 1900 | E5: 22 | F5: Informational | G5: How We Build High-Impact Online Courses | H5: How We Build High-Impact Online Courses | I5: Service / Pillar | J5: Secondary Keyword | L5: Mapped | M5: SEO Manager | N5: =IF(OR(C5="",E5=""),"",ROUND((C5/(E5+1))*IF(ISNUMBER(SEARCH("Commercial",F5)),1.25,1),1)) -> 3.9 | O5: How to build a course that actually gets results | P5: Build a course that actually gets results with our proven guide. Learn to design lessons that work. Start creating your high-impact program today. | Q5: Kajabi Service Page keywords | R5: 46230 | S5: Confirm current canonical URL and search intent
A6: KW-002 | B6: online course design best practices | C6: 40 | D6: 110 | E6: 23 | F6: Commercial | G6: How We Build High-Impact Online Courses | H6: How We Build High-Impact Online Courses | I6: Service / Pillar | J6: Secondary Keyword | L6: Mapped | M6: SEO Manager | N6: =IF(OR(C6="",E6=""),"",ROUND((C6/(E6+1))*IF(ISNUMBER(SEARCH("Commercial",F6)),1.25,1),1)) -> 2.1 | Q6: Kajabi Service Page keywords | R6: 46230 | S6: Confirm current canonical URL and search intent
A7: KW-003 | B7: online course launch | C7: 40 | D7: 70 | E7: 15 | F7: Informational | G7: How We Build High-Impact Online Courses | H7: How We Build High-Impact Online Courses | I7: Service / Pillar | J7: Secondary Keyword | L7: Mapped | M7: SEO Manager | N7: =IF(OR(C7="",E7=""),"",ROUND((C7/(E7+1))*IF(ISNUMBER(SEARCH("Commercial",F7)),1.25,1),1)) -> 2.5 | Q7: Kajabi Service Page keywords | R7: 46230 | S7: Confirm current canonical URL and search intent
A8: KW-004 | B8: how to create elearning courses | C8: 50 | D8: 160 | E8: 18 | F8: Informational | G8: How We Build High-Impact Online Courses | H8: How We Build High-Impact Online Courses | I8: Service / Pillar | J8: Secondary Keyword | L8: Mapped | M8: SEO Manager | N8: =IF(OR(C8="",E8=""),"",ROUND((C8/(E8+1))*IF(ISNUMBER(SEARCH("Commercial",F8)),1.25,1),1)) -> 2.6 | Q8: Kajabi Service Page keywords | R8: 46230 | S8: Confirm current canonical URL and search intent
A9: KW-005 | B9: building elearning courses | C9: 70 | D9: 240 | E9: 15 | F9: Informational | G9: How We Build High-Impact Online Courses | H9: How We Build High-Impact Online Courses | I9: Service / Pillar | J9: Secondary Keyword | L9: Mapped | M9: SEO Manager | N9: =IF(OR(C9="",E9=""),"",ROUND((C9/(E9+1))*IF(ISNUMBER(SEARCH("Commercial",F9)),1.25,1),1)) -> 4.4 | Q9: Kajabi Service Page keywords | R9: 46230 | S9: Confirm current canonical URL and search intent
A10: KW-006 | B10: how to make training interactive | C10: 30 | D10: 70 | E10: 18 | F10: Informational | G10: How We Build High-Impact Online Courses | H10: How We Build High-Impact Online Courses | I10: Service / Pillar | J10: Secondary Keyword | L10: Mapped | M10: SEO Manager | N10: =IF(OR(C10="",E10=""),"",ROUND((C10/(E10+1))*IF(ISNUMBER(SEARCH("Commercial",F10)),1.25,1),1)) -> 1.6 | Q10: Kajabi Service Page keywords | R10: 46230 | S10: Confirm current canonical URL and search intent
A11: KW-007 | B11: done for you course creation | C11: 70 | D11: 140 | E11: 7 | F11: Informational | G11: How We Build High-Impact Online Courses | H11: How We Build High-Impact Online Courses | I11: Service / Pillar | J11: Secondary Keyword | L11: Mapped | M11: SEO Manager | N11: =IF(OR(C11="",E11=""),"",ROUND((C11/(E11+1))*IF(ISNUMBER(SEARCH("Commercial",F11)),1.25,1),1)) -> 8.8 | Q11: Kajabi Service Page keywords | R11: 46230 | S11: Confirm current canonical URL and search intent
A12: KW-008 | B12: how to create and sell online courses | C12: 90 | D12: 220 | E12: 32 | F12: Informational | G12: How We Build High-Impact Online Courses | H12: How We Build High-Impact Online Courses | I12: Service / Pillar | J12: Secondary Keyword | L12: Mapped | M12: SEO Manager | N12: =IF(OR(C12="",E12=""),"",ROUND((C12/(E12+1))*IF(ISNUMBER(SEARCH("Commercial",F12)),1.25,1),1)) -> 2.7 | Q12: Kajabi Service Page keywords | R12: 46230 | S12: Confirm current canonical URL and search intent
A13: KW-009 | B13: how to create an online course pdf | C13: 70 | D13: 170 | E13: 0 | F13: Informational | G13: How We Build High-Impact Online Courses | H13: How We Build High-Impact Online Courses | I13: Service / Pillar | J13: Secondary Keyword | L13: Mapped | M13: SEO Manager | N13: =IF(OR(C13="",E13=""),"",ROUND((C13/(E13+1))*IF(ISNUMBER(SEARCH("Commercial",F13)),1.25,1),1)) -> 70 | Q13: Kajabi Service Page keywords | R13: 46230 | S13: Confirm current canonical URL and search intent
A14: KW-010 | B14: how to create an online course that sells | C14: 70 | D14: 270 | E14: 25 | F14: Commercial | G14: How We Build High-Impact Online Courses | H14: How We Build High-Impact Online Courses | I14: Service / Pillar | J14: Primary Keyword | L14: Mapped | M14: SEO Manager | N14: =IF(OR(C14="",E14=""),"",ROUND((C14/(E14+1))*IF(ISNUMBER(SEARCH("Commercial",F14)),1.25,1),1)) -> 3.4 | Q14: Kajabi Service Page keywords | R14: 46230 | S14: Confirm current canonical URL and search intent
A15: KW-011 | B15: best selling online courses | C15: 40 | D15: 230 | E15: 27 | F15: Informational | G15: How We Build High-Impact Online Courses | H15: How We Build High-Impact Online Courses | I15: Service / Pillar | J15: Secondary Keyword | L15: Mapped | M15: SEO Manager | N15: =IF(OR(C15="",E15=""),"",ROUND((C15/(E15+1))*IF(ISNUMBER(SEARCH("Commercial",F15)),1.25,1),1)) -> 1.4 | Q15: Kajabi Service Page keywords | R15: 46230 | S15: Confirm current canonical URL and search intent
A16: KW-012 | B16: best platform to create and sell online courses | C16: 30 | D16: 100 | G16: How We Build High-Impact Online Courses | H16: How We Build High-Impact Online Courses | I16: Service / Pillar | J16: Secondary Keyword | L16: Mapped | M16: SEO Manager | N16: =IF(OR(C16="",E16=""),"",ROUND((C16/(E16+1))*IF(ISNUMBER(SEARCH("Commercial",F16)),1.25,1),1)) | Q16: Kajabi Service Page keywords | R16: 46230 | S16: Confirm current canonical URL and search intent
A17: KW-013 | B17: how to create a course to sell | C17: 90 | D17: 250 | E17: 30 | F17: Informational | G17: How We Build High-Impact Online Courses | H17: How We Build High-Impact Online Courses | I17: Service / Pillar | J17: Secondary Keyword | L17: Mapped | M17: SEO Manager | N17: =IF(OR(C17="",E17=""),"",ROUND((C17/(E17+1))*IF(ISNUMBER(SEARCH("Commercial",F17)),1.25,1),1)) -> 2.9 | Q17: Kajabi Service Page keywords | R17: 46230 | S17: Confirm current canonical URL and search intent
A18: KW-014 | B18: online training delivery methods | C18: 40 | D18: 70 | E18: 4 | F18: Informational | G18: How We Deliver course | H18: How We Deliver course | I18: Service / Pillar | J18: Secondary Keyword | L18: Mapped | M18: SEO Manager | N18: =IF(OR(C18="",E18=""),"",ROUND((C18/(E18+1))*IF(ISNUMBER(SEARCH("Commercial",F18)),1.25,1),1)) -> 8 | O18: How We Deliver Professional Courses With Speed and Precision | P18: Get courses delivered with precision and speed. We handle the hard work so you don't have to. See how our professional team gets it done right. Learn more now. | Q18: Kajabi Service Page keywords | R18: 46230 | S18: Confirm current canonical URL and search intent
A19: KW-015 | B19: e-learning delivery methods | C19: 50 | D19: 80 | E19: 1 | F19: Commercial+Informational | I19: Unmapped | J19: Secondary Keyword | L19: Needs Mapping | M19: SEO Manager | N19: =IF(OR(C19="",E19=""),"",ROUND((C19/(E19+1))*IF(ISNUMBER(SEARCH("Commercial",F19)),1.25,1),1)) -> 31.3 | Q19: Kajabi Service Page keywords | R19: 46230 | S19: Assign to a suitable existing or new page
A20: KW-016 | B20: best service delivery courses | C20: 0 | D20: 10 | F20: Informational | I20: Unmapped | J20: Secondary Keyword | L20: Needs Mapping | M20: SEO Manager | N20: =IF(OR(C20="",E20=""),"",ROUND((C20/(E20+1))*IF(ISNUMBER(SEARCH("Commercial",F20)),1.25,1),1)) | Q20: Kajabi Service Page keywords | R20: 46230 | S20: Assign to a suitable existing or new page
A21: KW-017 | B21: deliver a course | C21: 0 | D21: 140 | E21: 9 | F21: Informational | I21: Unmapped | J21: Secondary Keyword | L21: Needs Mapping | M21: SEO Manager | N21: =IF(OR(C21="",E21=""),"",ROUND((C21/(E21+1))*IF(ISNUMBER(SEARCH("Commercial",F21)),1.25,1),1)) -> 0 | Q21: Kajabi Service Page keywords | R21: 46230 | S21: Assign to a suitable existing or new page
A22: KW-018 | B22: elearning delivery | C22: 70 | D22: 110 | E22: 6 | F22: Informational | I22: Unmapped | J22: Secondary Keyword | L22: Needs Mapping | M22: SEO Manager | N22: =IF(OR(C22="",E22=""),"",ROUND((C22/(E22+1))*IF(ISNUMBER(SEARCH("Commercial",F22)),1.25,1),1)) -> 10 | Q22: Kajabi Service Page keywords | R22: 46230 | S22: Assign to a suitable existing or new page
A23: KW-019 | B23: KEYWORD | F23: INTENT | G23: WORD TYPE | H23: WORD TYPE | I23: Service / Pillar | J23: Title | L23: Mapped | M23: SEO Manager | N23: =IF(OR(C23="",E23=""),"",ROUND((C23/(E23+1))*IF(ISNUMBER(SEARCH("Commercial",F23)),1.25,1),1)) | O23: Description | P23: Linking page | Q23: Kajabi Service Page keywords | R23: 46230 | S23: Confirm current canonical URL and search intent
A24: KW-020 | B24: kajabi online course platform | C24: 18100 | D24: 18100 | E24: 28 | F24: Informational | G24: Secondary Keyword | H24: Secondary Keyword | I24: Service / Pillar | J24: Secondary Keyword | L24: Mapped | M24: SEO Manager | N24: =IF(OR(C24="",E24=""),"",ROUND((C24/(E24+1))*IF(ISNUMBER(SEARCH("Commercial",F24)),1.25,1),1)) -> 624.1 | Q24: Kajabi Service Page keywords | R24: 46230 | S24: Confirm current canonical URL and search intent
A25: KW-021 | B25: kajabi online courses | C25: 90 | D25: 310 | F25: Informational | G25: Secondary Keyword | H25: Secondary Keyword | I25: Service / Pillar | J25: Expert Kajabi Course Setup to Scale Your Business-theEduAssist | L25: Mapped | M25: SEO Manager | N25: =IF(OR(C25="",E25=""),"",ROUND((C25/(E25+1))*IF(ISNUMBER(SEARCH("Commercial",F25)),1.25,1),1)) | O25: Scale your business with pro Kajabi course setup. theEduAssist handles the tech so you can teach. Book your setup call and launch your offer now. | P25: https://theeduassist.com/blog/7-powerful-kajabi-course-creation-services/ | Q25: Kajabi Service Page keywords | R25: 46230 | S25: Confirm current canonical URL and search intent
A26: KW-022 | B26: kajabi online course setup | F26: Informational | G26: Secondary Keyword | H26: Secondary Keyword | I26: Service / Pillar | J26: Secondary Keyword | L26: Mapped | M26: SEO Manager | N26: =IF(OR(C26="",E26=""),"",ROUND((C26/(E26+1))*IF(ISNUMBER(SEARCH("Commercial",F26)),1.25,1),1)) | P26: https://theeduassist.com/blog/kajabi-online-course-setup/ | Q26: Kajabi Service Page keywords | R26: 46230 | S26: Confirm current canonical URL and search intent
A27: KW-023 | B27: setup online course kajabi | F27: Informational | G27: Secondary Keyword | H27: Secondary Keyword | I27: Service / Pillar | J27: Secondary Keyword | L27: Mapped | M27: SEO Manager | N27: =IF(OR(C27="",E27=""),"",ROUND((C27/(E27+1))*IF(ISNUMBER(SEARCH("Commercial",F27)),1.25,1),1)) | P27: https://theeduassist.com/blog/kajabi-course-design-explained-how-to-create-online-course-in-2026/ | Q27: Kajabi Service Page keywords | R27: 46230 | S27: Confirm current canonical URL and search intent
A28: KW-024 | B28: kajabi course setup | F28: Informational | G28: Secondary Keyword | H28: Secondary Keyword | I28: Service / Pillar | J28: Secondary Keyword | L28: Mapped | M28: SEO Manager | N28: =IF(OR(C28="",E28=""),"",ROUND((C28/(E28+1))*IF(ISNUMBER(SEARCH("Commercial",F28)),1.25,1),1)) | P28: https://theeduassist.com/blog/kajabi-course-design/ | Q28: Kajabi Service Page keywords | R28: 46230 | S28: Confirm current canonical URL and search intent
A29: KW-025 | B29: online course setup | C29: 20 | D29: 90 | F29: Informational | G29: Secondary Keyword | H29: Secondary Keyword | I29: Service / Pillar | J29: Secondary Keyword | L29: Mapped | M29: SEO Manager | N29: =IF(OR(C29="",E29=""),"",ROUND((C29/(E29+1))*IF(ISNUMBER(SEARCH("Commercial",F29)),1.25,1),1)) | P29: https://theeduassist.com/blog/kajabi-drip-course-setup/ | Q29: Kajabi Service Page keywords | R29: 46230 | S29: Confirm current canonical URL and search intent
A30: KW-026 | B30: how to create a course on kajabi | C30: 30 | D30: 30 | F30: Informational | G30: Secondary Keyword | H30: Secondary Keyword | I30: Service / Pillar | J30: Secondary Keyword | L30: Mapped | M30: SEO Manager | N30: =IF(OR(C30="",E30=""),"",ROUND((C30/(E30+1))*IF(ISNUMBER(SEARCH("Commercial",F30)),1.25,1),1)) | Q30: Kajabi Service Page keywords | R30: 46230 | S30: Confirm current canonical URL and search intent
A31: KW-027 | B31: how to create a course in kajabi | C31: 20 | D31: 100 | F31: Informational | G31: Secondary Keyword | H31: Secondary Keyword | I31: Service / Pillar | J31: Secondary Keyword | L31: Mapped | M31: SEO Manager | N31: =IF(OR(C31="",E31=""),"",ROUND((C31/(E31+1))*IF(ISNUMBER(SEARCH("Commercial",F31)),1.25,1),1)) | Q31: Kajabi Service Page keywords | R31: 46230 | S31: Confirm current canonical URL and search intent
A32: KW-028 | B32: how to create a kajabi course | C32: 20 | D32: 30 | F32: Informational | G32: Secondary Keyword | H32: Secondary Keyword | I32: Service / Pillar | J32: Secondary Keyword | L32: Mapped | M32: SEO Manager | N32: =IF(OR(C32="",E32=""),"",ROUND((C32/(E32+1))*IF(ISNUMBER(SEARCH("Commercial",F32)),1.25,1),1)) | Q32: Kajabi Service Page keywords | R32: 46230 | S32: Confirm current canonical URL and search intent
A33: KW-029 | B33: Kajabi Course Setup Service | G33: Primary Keyword | H33: Primary Keyword | I33: Service / Pillar | J33: Secondary Keyword | L33: Mapped | M33: SEO Manager | N33: =IF(OR(C33="",E33=""),"",ROUND((C33/(E33+1))*IF(ISNUMBER(SEARCH("Commercial",F33)),1.25,1),1)) | Q33: Kajabi Service Page keywords | R33: 46230 | S33: Confirm current canonical URL and search intent
A34: KW-030 | B34: Kajabi services | C34: 40 | D34: 70 | E34: 31 | F34: Navigational | G34: Secondary Keyword | H34: Secondary Keyword | I34: Service / Pillar | J34: Secondary Keyword | L34: Mapped | M34: SEO Manager | N34: =IF(OR(C34="",E34=""),"",ROUND((C34/(E34+1))*IF(ISNUMBER(SEARCH("Commercial",F34)),1.25,1),1)) -> 1.3 | Q34: Kajabi Service Page keywords | R34: 46230 | S34: Confirm current canonical URL and search intent
A35: KW-031 | B35: kajabi funnels | C35: 20 | D35: 220 | F35: Informational | G35: Primary Keyword | H35: Primary Keyword | I35: Service / Pillar | J35: Expert Kajabi Website & Funnel Setup for More Sales | L35: Mapped | M35: SEO Manager | N35: =IF(OR(C35="",E35=""),"",ROUND((C35/(E35+1))*IF(ISNUMBER(SEARCH("Commercial",F35)),1.25,1),1)) | O35: Your Kajabi site should work for you. We build high-converting funnels that boost your revenue. Book your setup call now. | P35: https://theeduassist.com/blog/kajabi-website-funnel-services/ | Q35: Kajabi Service Page keywords | R35: 46230 | S35: Confirm current canonical URL and search intent
A36: KW-032 | B36: kajabi website | C36: 390 | D36: 820 | E36: 21 | F36: Navigational | G36: Primary Keyword | H36: Primary Keyword | I36: Service / Pillar | J36: Secondary Keyword | L36: Mapped | M36: SEO Manager | N36: =IF(OR(C36="",E36=""),"",ROUND((C36/(E36+1))*IF(ISNUMBER(SEARCH("Commercial",F36)),1.25,1),1)) -> 17.7 | P36: https://theeduassist.com/blog/kajabi-website-funnel-services/ | Q36: Kajabi Service Page keywords | R36: 46230 | S36: Confirm current canonical URL and search intent
A37: KW-033 | B37: kajabi website expert | C37: 70 | D37: 70 | E37: 9 | F37: Commercial | G37: Secondary Keyword | H37: Secondary Keyword | I37: Service / Pillar | J37: Secondary Keyword | L37: Mapped | M37: SEO Manager | N37: =IF(OR(C37="",E37=""),"",ROUND((C37/(E37+1))*IF(ISNUMBER(SEARCH("Commercial",F37)),1.25,1),1)) -> 8.8 | Q37: Kajabi Service Page keywords | R37: 46230 | S37: Confirm current canonical URL and search intent
A38: KW-034 | B38: kajabi sales funnel | C38: 20 | D38: 70 | F38: Informational | G38: Secondary Keyword | H38: Secondary Keyword | I38: Service / Pillar | J38: Secondary Keyword | L38: Mapped | M38: SEO Manager | N38: =IF(OR(C38="",E38=""),"",ROUND((C38/(E38+1))*IF(ISNUMBER(SEARCH("Commercial",F38)),1.25,1),1)) | Q38: Kajabi Service Page keywords | R38: 46230 | S38: Confirm current canonical URL and search intent
A39: KW-035 | B39: best funnels to use on kajabi | F39: Informational | G39: Secondary Keyword | H39: Secondary Keyword | I39: Service / Pillar | J39: Secondary Keyword | L39: Mapped | M39: SEO Manager | N39: =IF(OR(C39="",E39=""),"",ROUND((C39/(E39+1))*IF(ISNUMBER(SEARCH("Commercial",F39)),1.25,1),1)) | Q39: Kajabi Service Page keywords | R39: 46230 | S39: Confirm current canonical URL and search intent
A40: KW-036 | B40: kajabi course upload services | G40: Primary Keyword | H40: Primary Keyword | I40: Service / Pillar | J40: Professional Kajabi Course Upload Service | We Value Your Time | L40: Mapped | M40: SEO Manager | N40: =IF(OR(C40="",E40=""),"",ROUND((C40/(E40+1))*IF(ISNUMBER(SEARCH("Commercial",F40)),1.25,1),1)) | O40: Need your course live? Our professional Kajabi course upload service takes the stress away. We build it right the first time. Hire our experts here. | Q40: Kajabi Service Page keywords | R40: 46230 | S40: Confirm current canonical URL and search intent
A41: KW-037 | B41: kajabi.services | G41: Secondary Keyword | H41: Secondary Keyword | I41: Service / Pillar | J41: Secondary Keyword | L41: Mapped | M41: SEO Manager | N41: =IF(OR(C41="",E41=""),"",ROUND((C41/(E41+1))*IF(ISNUMBER(SEARCH("Commercial",F41)),1.25,1),1)) | Q41: Kajabi Service Page keywords | R41: 46230 | S41: Confirm current canonical URL and search intent
...

Sheet 03 Content Pipeline
A1: Content and Page Production Pipeline
A2: Track service pages, articles, comparisons, case studies and resources from brief through indexing and refresh.
A4: Content ID | B4: Content / Page | C4: Type | D4: Cluster | E4: Primary Keyword | F4: Intent | G4: Funnel Stage | H4: Current URL | I4: Draft / Brief Link | J4: Status | K4: Priority | L4: Owner | M4: Due Date | N4: Publish Date | O4: Primary CTA | P4: Internal Links to Add | Q4: Schema | R4: Index Status | S4: Last Refresh | T4: Notes
A5: CNT-001 | B5: Homepage | C5: Core Page | D5: Brand / E-learning Agency | E5: eLearning development company | F5: Commercial | G5: Decision | H5: https://www.theeduassist.com/ | J5: Published | K5: Critical | L5: SEO Manager | O5: Get a 24–48 Hour Review | P5: Services; Kajabi; Case Studies; Pricing; Insights | Q5: Organization; WebSite; Breadcrumb | R5: Indexed | T5: Monitor CTR and conversions
A6: CNT-002 | B6: Services Hub | C6: Core Page | D6: Services | E6: eLearning services | F6: Commercial | G6: Consideration | H6: https://www.theeduassist.com/services/ | J6: Published | K6: Critical | L6: SEO Manager | O6: Get a 24–48 Hour Review | P6: All service pages; case studies | Q6: ItemList; Service; Breadcrumb | R6: Needs Review | T6: Confirm current canonical
A7: CNT-003 | B7: Kajabi Services Hub | C7: Core Page | D7: Kajabi | E7: Kajabi services | F7: Commercial | G7: Consideration | H7: https://www.theeduassist.com/kajabi-services/ | J7: Published | K7: High | L7: SEO Manager | O7: Get a Kajabi Review | P7: Kajabi service pages; case studies | Q7: Service; Breadcrumb | R7: Needs Review
A8: CNT-004 | B8: Case Studies Hub | C8: Core Page | D8: Proof / Results | E8: eLearning case studies | F8: Commercial | G8: Decision | H8: https://www.theeduassist.com/case-studies/ | J8: Published | K8: High | L8: Content Lead | O8: Discuss a Project | P8: Relevant services; review CTA | Q8: CollectionPage; Breadcrumb | R8: Needs Review
A9: CNT-005 | B9: Pricing | C9: Core Page | D9: Pricing | E9: eLearning development pricing | F9: Commercial | G9: Decision | H9: https://www.theeduassist.com/pricing/ | J9: Published | K9: High | L9: SEO Manager | O9: Request Review | P9: Services; case studies; contact | Q9: Service; Breadcrumb | R9: Needs Review
A10: CNT-006 | B10: About Us | C10: Core Page | D10: Trust | E10: TheEduAssist | F10: Navigational | G10: Decision | H10: https://www.theeduassist.com/about/ | J10: Needs Review | K10: High | L10: Content Lead | M10: 46235 | O10: Talk to Our Team | P10: Contact; case studies; careers | Q10: AboutPage; Organization; Breadcrumb | R10: Needs Revalidation | T10: Revalidate live page before editing
A11: CNT-007 | B11: Contact Us | C11: Core Page | D11: Conversion | E11: contact TheEduAssist | F11: Navigational | G11: Decision | H11: https://www.theeduassist.com/contact/ | J11: Needs Review | K11: Critical | L11: SEO Manager | M11: 46234 | O11: Submit Enquiry | P11: Services; review pathway | Q11: ContactPage; Organization; Breadcrumb | R11: Needs Revalidation | T11: Confirm form completion and key event tracking
A12: CNT-008 | B12: 24–48 Hour Review | C12: Conversion Page | D12: Lead Generation | E12: eLearning project review | F12: Commercial | G12: Decision | H12: https://www.theeduassist.com/book-free-audit/ | J12: Published | K12: Critical | L12: SEO Manager | O12: Submit Review | P12: Services; pricing; proof | Q12: Service; Breadcrumb | R12: Needs Review | T12: Track form conversion
A13: CNT-009 | B13: Quality Assurance & Testing | C13: Service Page | D13: Quality Assurance & Testing | F13: Commercial | G13: Consideration | I13: https://docs.google.com/document/d/1f56qgIxvQ8BxjrmBfliB3yKROdXTLpazw-3e6_4kuHQ/edit?tab=t.yg0q4iabl9v4 | J13: Brief Available | K13: High | L13: Content Lead | O13: Get a 24–48 Hour Review | P13: Homepage; Services; relevant case study | Q13: Service; Breadcrumb | R13: Not Checked | T13: Legacy source data. Confirm whether page remains in current scope.
A14: CNT-010 | B14: custom elearning Content Development | C14: Service Page | D14: custom elearning Content Development | F14: Commercial | G14: Consideration | I14: https://docs.google.com/document/d/1f56qgIxvQ8BxjrmBfliB3yKROdXTLpazw-3e6_4kuHQ/edit?tab=t.5lutc4nxjx8 | J14: Brief Available | K14: High | L14: Content Lead | O14: Get a 24–48 Hour Review | P14: Homepage; Services; relevant case study | Q14: Service; Breadcrumb | R14: Not Checked | T14: Legacy source data. Confirm whether page remains in current scope.
A15: CNT-011 | B15: Audio & Video Production for eLearning | C15: Service Page | D15: Audio & Video Production for eLearning | F15: Commercial | G15: Consideration | I15: https://docs.google.com/document/d/1f56qgIxvQ8BxjrmBfliB3yKROdXTLpazw-3e6_4kuHQ/edit?tab=t.js459uanpi6m#heading=h.go603l3bm2g | J15: Brief Available | K15: High | L15: Content Lead | O15: Get a 24–48 Hour Review | P15: Homepage; Services; relevant case study | Q15: Service; Breadcrumb | R15: Not Checked | T15: Legacy source data. Confirm whether page remains in current scope.
A16: CNT-012 | B16: Learning Strategy & Consulting | C16: Service Page | D16: Learning Strategy & Consulting | F16: Commercial | G16: Consideration | I16: https://docs.google.com/document/d/1f56qgIxvQ8BxjrmBfliB3yKROdXTLpazw-3e6_4kuHQ/edit?tab=t.ovptwam8j30h#heading=h.d3vlvgz8zawx | J16: Brief Available | K16: High | L16: Content Lead | O16: Get a 24–48 Hour Review | P16: Homepage; Services; relevant case study | Q16: Service; Breadcrumb | R16: Not Checked | T16: Legacy source data. Confirm whether page remains in current scope.
A17: CNT-013 | B17: LMS implementation and migration | C17: Service Page | D17: LMS implementation and migration | F17: Commercial | G17: Consideration | I17: https://docs.google.com/document/d/1f56qgIxvQ8BxjrmBfliB3yKROdXTLpazw-3e6_4kuHQ/edit?tab=t.tohiqah9td47#heading=h.kd718vxvhsby | J17: Brief Available | K17: High | L17: Content Lead | O17: Get a 24–48 Hour Review | P17: Homepage; Services; relevant case study | Q17: Service; Breadcrumb | R17: Not Checked | T17: Legacy source data. Confirm whether page remains in current scope.
A18: CNT-014 | B18: Legacy Content Conversion Services | C18: Service Page | D18: Legacy Content Conversion Services | F18: Commercial | G18: Consideration | I18: https://docs.google.com/document/d/1f56qgIxvQ8BxjrmBfliB3yKROdXTLpazw-3e6_4kuHQ/edit?tab=t.o5zfykc0ue96#heading=h.yzndcpkh5oz9 | J18: Brief Available | K18: High | L18: Content Lead | O18: Get a 24–48 Hour Review | P18: Homepage; Services; relevant case study | Q18: Service; Breadcrumb | R18: Not Checked | T18: Legacy source data. Confirm whether page remains in current scope.
A19: CNT-015 | B19: Dashboard and Analytics | C19: Service Page | D19: Dashboard and Analytics | F19: Commercial | G19: Consideration | I19: https://docs.google.com/document/d/1f56qgIxvQ8BxjrmBfliB3yKROdXTLpazw-3e6_4kuHQ/edit?tab=t.kzfnsxwralxw | J19: Brief Available | K19: High | L19: Content Lead | O19: Get a 24–48 Hour Review | P19: Homepage; Services; relevant case study | Q19: Service; Breadcrumb | R19: Not Checked | T19: Legacy source data. Confirm whether page remains in current scope.
A20: CNT-016 | B20: Instructional & UI/UX Design | C20: Service Page | D20: Instructional & UI/UX Design | F20: Commercial | G20: Consideration | I20: https://theeduassist.com/2508-2/ | J20: Brief Available | K20: High | L20: Content Lead | O20: Get a 24–48 Hour Review | P20: Homepage; Services; relevant case study | Q20: Service; Breadcrumb | R20: Not Checked | T20: Legacy source data. Confirm whether page remains in current scope.
A21: CNT-017 | B21: Microlearning & Microsimulations | C21: Service Page | D21: Microlearning & Microsimulations | F21: Commercial | G21: Consideration | I21: https://docs.google.com/document/d/1f56qgIxvQ8BxjrmBfliB3yKROdXTLpazw-3e6_4kuHQ/edit?tab=t.ux8re1anxvxk | J21: Brief Available | K21: High | L21: Content Lead | O21: Get a 24–48 Hour Review | P21: Homepage; Services; relevant case study | Q21: Service; Breadcrumb | R21: Not Checked | T21: Legacy source data. Confirm whether page remains in current scope.
A22: CNT-018 | B22: Gamification | C22: Service Page | D22: Gamification | F22: Commercial | G22: Consideration | I22: https://docs.google.com/document/d/1f56qgIxvQ8BxjrmBfliB3yKROdXTLpazw-3e6_4kuHQ/edit?tab=t.cxbuvw6ey5v5 | J22: Brief Available | K22: High | L22: Content Lead | O22: Get a 24–48 Hour Review | P22: Homepage; Services; relevant case study | Q22: Service; Breadcrumb | R22: Not Checked | T22: Legacy source data. Confirm whether page remains in current scope.
A23: CNT-019 | B23: Scenario-Based Learning | C23: Service Page | D23: Scenario-Based Learning | F23: Commercial | G23: Consideration | I23: https://docs.google.com/document/d/1f56qgIxvQ8BxjrmBfliB3yKROdXTLpazw-3e6_4kuHQ/edit?tab=t.kb09wkbrauul | J23: Brief Available | K23: High | L23: Content Lead | O23: Get a 24–48 Hour Review | P23: Homepage; Services; relevant case study | Q23: Service; Breadcrumb | R23: Not Checked | T23: Legacy source data. Confirm whether page remains in current scope.
A24: CNT-020 | B24: K-12 Education Services | C24: Service Page | D24: K-12 Education Services | F24: Commercial | G24: Consideration | I24: https://docs.google.com/document/d/1f56qgIxvQ8BxjrmBfliB3yKROdXTLpazw-3e6_4kuHQ/edit?tab=t.79y8aqx5j6vf | J24: Brief Available | K24: High | L24: Content Lead | O24: Get a 24–48 Hour Review | P24: Homepage; Services; relevant case study | Q24: Service; Breadcrumb | R24: Not Checked | T24: Legacy source data. Confirm whether page remains in current scope.
... A38: CNT-034 | B38: Off-the-Shelf Corporate Courses/Ecourses OFF the shelf | C38: Service Page | D38: Off-the-Shelf Corporate Courses/Ecourses OFF the shelf | F38: Commercial | G38: Consideration | I38: https://www.tuvsud.com/en-in/store/academy-in/corporate-subscription-customized-content-solutions/customised-content-creation | J38: Brief Available | K38: Medium | L38: Content Lead | O38: Get a 24–48 Hour Review | P38: Homepage; Services; relevant case study | Q38: Service; Breadcrumb | R38: Not Checked | T38: Legacy source data. Confirm whether page remains in current scope.

Sheet 04 Technical Issues
A1: Technical SEO Issue Log
A2: Log verified issues only. Old findings are marked Needs Revalidation until checked against the current www deployment.
A4: Issue ID | B4: Detected Date | C4: Source | D4: Severity | E4: Category | F4: URL | G4: Issue | H4: SEO / Business Impact | I4: Recommended Fix | J4: Owner | K4: Status | L4: Due Date | M4: Evidence | N4: Validation Method | O4: Resolved Date | P4: Recurrence | Q4: Notes
A5: ISS-001 | B5: 46230 | C5: Legacy workbook | D5: Critical | E5: Canonical / Redirects | F5: https://www.theeduassist.com/ | G5: Active workbook contained many non-www URLs; current canonical is www | H5: Duplicate signals and incorrect reporting if legacy URLs remain in operations | I5: Verify one-hop redirects, canonical tags, sitemap and internal links use www | J5: Developer | K5: Needs Revalidation | L5: 46232 | N5: URL Inspection + curl + sitemap review | P5: One-time
A6: ISS-002 | B6: 46230 | C6: Legacy workbook | D6: Critical | E6: Broken Links | F6: https://theeduassist.com/case-study-1/ | G6: Legacy case study URL previously reported as 404 and visible on homepage | H6: Broken user journey and crawl waste | I6: Revalidate current featured-project cards; fix links or redirects | J6: Developer | K6: Needs Revalidation | L6: 46233 | N6: Crawler + manual click test | P6: One-time | Q6: Also check case-study-2 and case-study-3
A7: ISS-003 | B7: 46230 | C7: Legacy workbook | D7: High | E7: On-page / Conversion | F7: https://www.theeduassist.com/contact/ | G7: Legacy report mentioned missing schema, weak internal linking and no post-submit redirect | H7: May weaken trust, tracking and conversion measurement | I7: Check live page; add appropriate schema, internal links, confirmation state and GA4 key event if missing | J7: SEO Manager | K7: Needs Revalidation | L7: 46234 | N7: Manual test + Rich Results Test + GA4 DebugView | P7: Quarterly
A8: ISS-004 | B8: 46230 | C8: Legacy workbook | D8: High | E8: Trust / On-page | F8: https://www.theeduassist.com/about/ | G8: Legacy report mentioned weak H1, company story, team proof and credentials | H8: Reduced trust and weaker decision-stage support | I8: Review live page and strengthen verifiable company information, team disciplines, proof and CTA | J8: Content Lead | K8: Needs Revalidation | L8: 46235 | N8: Manual content QA + URL Inspection | P8: Quarterly
A9: ISS-005 | B9: 46230 | C9: Workbook audit | D9: High | E9: Content Governance | F9: Active keyword plan | G9: AR/VR keywords remained in old active research although service scope removed | H9: Wastes team time and creates irrelevant content plans | I9: Keep AR/VR only in raw archive; do not create active tasks or pages | J9: SEO Manager | K9: Resolved | L9: 46230 | M9: Redesigned workbook | N9: Review active keyword and content tabs | O9: 46230 | P9: One-time
A10: ISS-006 | B10: 46230 | C10: Workbook audit | D10: High | E10: Backlinks | F10: Legacy backlink export | G10: Raw list contains many high-authority but irrelevant/unrealistic domains | H10: Can cause wasted outreach and link-spam risk | I10: Qualify for topical relevance, editorial fit, realistic route and policy safety before outreach | J10: Outreach | K10: Open | L10: 46240 | N10: Manual relevance and risk review | P10: Monthly
A11: ISS-007 | B11: 46230 | C11: Recommended control | D11: Critical | E11: Analytics | F11: GA4 / forms | G11: SEO reporting does not yet include verified leads and conversion rate in the legacy data | H11: Team may optimize vanity metrics instead of business outcomes | I11: Track review form, contact, consultation and RFP key events; add to monthly performance sheet | J11: Developer | K11: Open | L11: 46239 | N11: GA4 DebugView + form test | P11: Monthly
A12: ISS-008 | B12: 46230 | C12: Recommended control | D12: High | E12: Structured Data | F12: Site templates | G12: Schema must match visible page content and be monitored after deployment | H12: Incorrect markup can lose rich-result eligibility | I12: Validate applicable Organization, Service, Article and Breadcrumb markup; do not mark hidden or irrelevant content | J12: Developer | K12: Open | L12: 46241 | N12: Rich Results Test + Search Console enhancements | P12: On deploy
A13: ISS-009 | B13: 46230 | C13: Recommended control | D13: High | E13: Indexing | F13: XML sitemap | G13: Sitemap should contain only canonical, indexable URLs intended for search | H13: Noncanonical or obsolete URLs slow QA and confuse reporting | I13: Validate sitemap after every routing/content migration; submit in GSC and Bing | J13: Developer | K13: Open | L13: 46236 | N13: Sitemap validation + URL inspection | P13: On deploy
A14: ISS-010 | B14: 46230 | C14: Recommended control | D14: Medium | E14: Core Web Vitals | F14: Key templates | G14: LCP, INP and CLS are not recorded in the legacy performance tracker | H14: Performance regressions may go unnoticed | I14: Record field data monthly and create tasks for poor URL groups | J14: SEO Manager | K14: Open | L14: 46239 | N14: Search Console CWV + PageSpeed Insights | P14: Monthly

Sheet 05 Performance
A1: SEO Performance and Business Outcomes
A2: Enter one row per reporting period. Use the same data source and date range each time. Record leads and conversion rate alongside visibility metrics.
A4: Date | B4: Organic Traffic | C4: Organic Keywords | D4: Authority | E4: Referring Domains | F4: Backlinks | G4: Dofollow | H4: Nofollow | I4: AI Visibility | J4: AI Mentions | K4: Cited Pages | L4: GSC Clicks | M4: GSC Impressions | N4: GSC CTR | O4: Average Position | P4: GA4 Organic Sessions | Q4: Organic Leads | R4: Conversion Rate | S4: LCP (s) | T4: INP (ms) | U4: CLS | V4: Notes
A5: 46149 | B5: 3900 | C5: 201 | D5: 8 | E5: 107 | F5: 246 | G5: 205 | H5: 41 | I5: 14 | J5: 2 | K5: 51 | R5: =IF(OR(P5="",Q5=""),"",Q5/P5) | V5: Legacy snapshot; source details not recorded
A6: 46167 | B6: 2400 | C6: 223 | D6: 11 | E6: 112 | F6: 256 | G6: 210 | H6: 46 | I6: 14 | J6: 2 | K6: 52 | R6: =IF(OR(P6="",Q6=""),"",Q6/P6) | V6: Legacy snapshot; source details not recorded
A7: 46174 | B7: 4400 | C7: 245 | D7: 11 | E7: 113 | F7: 244 | G7: 198 | H7: 46 | I7: 14 | J7: 1 | K7: 53 | R7: =IF(OR(P7="",Q7=""),"",Q7/P7) | V7: Legacy snapshot; source details not recorded
R8: =IF(OR(P8="",Q8=""),"",Q8/P8)
R9: =IF(OR(P9="",Q9=""),"",Q9/P9)
R10: =IF(OR(P10="",Q10=""),"",Q10/P10)
R11: =IF(OR(P11="",Q11=""),"",Q11/P11)
R12: =IF(OR(P12="",Q12=""),"",Q12/P12)
R13: =IF(OR(P13="",Q13=""),"",Q13/P13)
R14: =IF(OR(P14="",Q14=""),"",Q14/P14)
R15: =IF(OR(P15="",Q15=""),"",Q15/P15)
R16: =IF(OR(P16="",Q16=""),"",Q16/P16)
R17: =IF(OR(P17="",Q17=""),"",Q17/P17)
R18: =IF(OR(P18="",Q18=""),"",Q18/P18)
R19: =IF(OR(P19="",Q19=""),"",Q19/P19)
... R104: =IF(OR(P104="",Q104=""),"",Q104/P104)

Sheet 06 Competitors
A1: Competitor Benchmark and Gap Tracker
A2: Metrics below are an April 2026 legacy snapshot. Refresh before making decisions and record a concrete content or link gap, not only numbers.
A4: Competitor ID | B4: Competitor | C4: Organic Traffic | D4: Organic Keywords | E4: Authority | F4: Backlinks | G4: AI Visibility | H4: AI Mentions | I4: Snapshot Date | J4: Refresh Status | K4: Top Strength | L4: Content Gap for TheEduAssist | M4: Link Gap / Source | N4: Priority | O4: Owner | P4: Last Checked | Q4: Next Action | R4: Notes
A5: COM-01 | B5: https://elearning.folio3.com | C5: 325 | D5: 930 | E5: 43 | F5: 374 | G5: 19 | H5: 515 | I5: 46141 | J5: Refresh Needed | N5: Medium | O5: SEO Manager | Q5: Refresh metrics and identify one replicable content advantage
A6: COM-02 | B6: https://www.kytewayelearning.com/ | C6: 763 | D6: 907 | E6: 22 | F6: 42500 | G6: 22 | H6: 32 | I6: 46141 | J6: Refresh Needed | N6: Medium | O6: SEO Manager | Q6: Refresh metrics and identify one replicable content advantage
A7: COM-03 | B7: https://www.eidesign.net/ | C7: 1400 | D7: 2500 | E7: 29 | F7: 21400 | G7: 21 | H7: 40 | I7: 46141 | J7: Refresh Needed | N7: Medium | O7: SEO Manager | Q7: Refresh metrics and identify one replicable content advantage
A8: COM-04 | B8: https://bluecarrot.io/ | C8: 906 | D8: 2000 | E8: 28 | F8: 4000 | G8: 15 | H8: 47 | I8: 46141 | J8: Refresh Needed | N8: Medium | O8: SEO Manager | Q8: Refresh metrics and identify one replicable content advantage
A9: COM-05 | B9: https://elearning.company/ | C9: 575 | D9: 446 | E9: 25 | F9: 1800 | G9: 14 | H9: 3 | I9: 46141 | J9: Refresh Needed | N9: Medium | O9: SEO Manager | Q9: Refresh metrics and identify one replicable content advantage
A10: COM-06 | B10: https://www.acadecraft.com/ | C10: 4700 | D10: 6000 | E10: 31 | F10: 91100 | G10: 25 | H10: 34 | I10: 46141 | J10: Refresh Needed | N10: Medium | O10: SEO Manager | Q10: Refresh metrics and identify one replicable content advantage
A11: COM-07 | B11: https://qquench.ai/our-services/e-learning/ | C11: 4 | D11: 39 | E11: 6 | F11: 257 | G11: 0 | H11: 0 | I11: 46141 | J11: Refresh Needed | N11: Medium | O11: SEO Manager | Q11: Refresh metrics and identify one replicable content advantage
A12: COM-08 | B12: https://redchipsolutions.com/ | C12: 210 | D12: 225 | E12: 20 | F12: 848 | G12: 14 | H12: 0 | I12: 46141 | J12: Refresh Needed | N12: Medium | O12: SEO Manager | Q12: Refresh metrics and identify one replicable content advantage
A13: COM-09 | B13: https://piogroup.net/ | C13: 905 | D13: 1200 | E13: 22 | F13: 2600 | G13: 14 | H13: 2 | I13: 46141 | J13: Refresh Needed | N13: Medium | O13: SEO Manager | Q13: Refresh metrics and identify one replicable content advantage
A14: COM-10 | B14: https://www.learningeverest.com/ | C14: 6800 | D14: 9500 | E14: 31 | F14: 42100 | G14: 16 | H14: 19 | I14: 46141 | J14: Refresh Needed | N14: Medium | O14: SEO Manager | Q14: Refresh metrics and identify one replicable content advantage
A15: COM-11 | B15: https://stratbeans.com/ | C15: 1100 | D15: 2400 | E15: 27 | F15: 2400 | G15: 14 | H15: 21 | I15: 46141 | J15: Refresh Needed | N15: Medium | O15: SEO Manager | Q15: Refresh metrics and identify one replicable content advantage
A16: COM-12 | B16: https://www.swiftelearningservices.com/ | C16: 892 | D16: 4300 | E16: 28 | F16: 41000 | G16: 18 | H16: 37 | I16: 46141 | J16: Refresh Needed | N16: Medium | O16: SEO Manager | Q16: Refresh metrics and identify one replicable content advantage
... A38: COM-34 | B38: https://jupitered.com/ | C38: 789800 | D38: 6000 | E38: 51 | F38: 66900 | G38: 32 | H38: 120 | I38: 46141 | J38: Refresh Needed | N38: Medium | O38: SEO Manager | Q38: Refresh metrics and identify one replicable content advantage

Sheet 07 Link Opportunities
A1: Link Opportunity Qualification
A2: Raw domains are not outreach targets until they pass relevance, realism and risk checks. Avoid link exchanges, paid ranking links and low-quality directories.
A4: Opportunity ID | B4: Domain | C4: Example URL | D4: Authority | E4: Monthly Visits | F4: Why Relevant | G4: Opportunity Type | H4: Target Page | I4: Contact / Submission Route | J4: Risk Check | K4: Status | L4: Owner | M4: Last Checked | N4: Next Step | O4: Notes
A5: LNK-001 | B5: medium.com | C5: https://medium.com/ | D5: 97 | E5: 116000000 | F5: Needs manual topical review | G5: Editorial contribution / resource inclusion | J5: Manual review required | K5: Unqualified | L5: Outreach | N5: Confirm relevance and realistic outreach path | O5: Legacy competitor/export source
A6: LNK-002 | B6: businessinsider.com | C6: www.emarketer.com | D6: 91 | E6: 77300000 | F6: Needs manual topical review | G6: Editorial contribution / resource inclusion | J6: Manual review required | K6: Unqualified | L6: Outreach | N6: Confirm relevance and realistic outreach path | O6: Legacy competitor/export source
A7: LNK-003 | B7: business-standard.com | C7: feedback@business-standard.com | D7: 84 | E7: 6900000 | F7: Needs manual topical review | G7: Editorial contribution / resource inclusion | J7: Manual review required | K7: Unqualified | L7: Outreach | N7: Confirm relevance and realistic outreach path | O7: Legacy competitor/export source
A8: LNK-004 | B8: telkomuniversity.ac.id | D8: 68 | E8: 2700000 | F8: Needs manual topical review | G8: Editorial contribution / resource inclusion | J8: Manual review required | K8: Unqualified | L8: Outreach | N8: Confirm relevance and realistic outreach path | O8: Legacy competitor/export source
A9: LNK-005 | B9: bestcolleges.com | D9: 63 | E9: 959000 | F9: Needs manual topical review | G9: Editorial contribution / resource inclusion | J9: Manual review required | K9: Unqualified | L9: Outreach | N9: Confirm relevance and realistic outreach path | O9: Legacy competitor/export source
A10: LNK-006 | B10: jobsdb.com | D10: 62 | E10: 5400000 | F10: Needs manual topical review | G10: Editorial contribution / resource inclusion | J10: Manual review required | K10: Unqualified | L10: Outreach | N10: Confirm relevance and realistic outreach path | O10: Legacy competitor/export source
A11: LNK-007 | B11: designrush.com | D11: 59 | E11: 639000 | F11: Needs manual topical review | G11: Editorial contribution / resource inclusion | J11: Manual review required | K11: Unqualified | L11: Outreach | N11: Confirm relevance and realistic outreach path | O11: Legacy competitor/export source
A12: LNK-008 | B12: aihr.com | D12: 58 | E12: 537000 | F12: Needs manual topical review | G12: Editorial contribution / resource inclusion | J12: Manual review required | K12: Unqualified | L12: Outreach | N12: Confirm relevance and realistic outreach path | O12: Legacy competitor/export source
A13: LNK-009 | B13: shrm.org | D13: 57 | E13: 2900000 | F13: Needs manual topical review | G13: Editorial contribution / resource inclusion | J13: Manual review required | K13: Unqualified | L13: Outreach | N13: Confirm relevance and realistic outreach path | O13: Legacy competitor/export source
A14: LNK-010 | B14: elearningindustry.com | D14: 54 | E14: 335000 | F14: Needs manual topical review | G14: Editorial contribution / resource inclusion | J14: Manual review required | K14: Unqualified | L14: Outreach | N14: Confirm relevance and realistic outreach path | O14: Legacy competitor/export source
A15: LNK-011 | B15: fortunebusinessinsights.com | D15: 53 | E15: 605000 | F15: Needs manual topical review | G15: Editorial contribution / resource inclusion | J15: Manual review required | K15: Unqualified | L15: Outreach | N15: Confirm relevance and realistic outreach path | O15: Legacy competitor/export source
A16: LNK-012 | B16: 360learning.com | D16: 49 | E16: 906000 | F16: Needs manual topical review | G16: Editorial contribution / resource inclusion | J16: Manual review required | K16: Unqualified | L16: Outreach | N16: Confirm relevance and realistic outreach path | O16: Legacy competitor/export source
A17: LNK-013 | B17: breezy.hr | D17: 47 | E17: 4600000 | F17: Needs manual topical review | G17: Editorial contribution / resource inclusion | J17: Manual review required | K17: Unqualified | L17: Outreach | N17: Confirm relevance and realistic outreach path | O17: Legacy competitor/export source
A18: LNK-014 | B18: trainingmag.com | D18: 45 | E18: 32600 | F18: Needs manual topical review | G18: Editorial contribution / resource inclusion | J18: Manual review required | K18: Unqualified | L18: Outreach | N18: Confirm relevance and realistic outreach path | O18: Legacy competitor/export source
A19: LNK-015 | B19: hotelcareer.de | D19: 45 | E19: 1100000 | F19: Needs manual topical review | G19: Editorial contribution / resource inclusion | J19: Manual review required | K19: Unqualified | L19: Outreach | N19: Confirm relevance and realistic outreach path | O19: Legacy competitor/export source
... A134: LNK-130 | B134: learnpatch.com | D134: 20 | E134: 170 | F134: Needs manual topical review | G134: Editorial contribution / resource inclusion | J134: Manual review required | K134: Unqualified | L134: Outreach | N134: Confirm relevance and realistic outreach path | O134: Legacy competitor/export source
A135: LNK-131 | B135: archylearning.com | D135: 19 | F135: Needs manual topical review | G135: Editorial contribution / resource inclusion | J135: Manual review required | K135: Unqualified | L135: Outreach | N135: Confirm relevance and realistic outreach path | O135: Legacy competitor/export source
A136: LNK-132 | B136: ill-career.co.jp | D136: 19 | F136: Needs manual topical review | G136: Editorial contribution / resource inclusion | J136: Manual review required | K136: Unqualified | L136: Outreach | N136: Confirm relevance and realistic outreach path | O136: Legacy competitor/export source
A137: LNK-133 | B137: peopleopsjobs.io | D137: 19 | E137: 6500 | F137: Needs manual topical review | G137: Editorial contribution / resource inclusion | J137: Manual review required | K137: Unqualified | L137: Outreach | N137: Confirm relevance and realistic outreach path | O137: Legacy competitor/export source
A138: LNK-134 | B138: businessseek.biz | D138: 18 | E138: 19300 | F138: Needs manual topical review | G138: Editorial contribution / resource inclusion | J138: Manual review required | K138: Unqualified | L138: Outreach | N138: Confirm relevance and realistic outreach path | O138: Legacy competitor/export source
A139: LNK-135 | B139: careertown.net | D139: 18 | E139: 856 | F139: Needs manual topical review | G139: Editorial contribution / resource inclusion | J139: Manual review required | K139: Unqualified | L139: Outreach | N139: Confirm relevance and realistic outreach path | O139: Legacy competitor/export source
