Workbook

Sheet Daily reports
B1: Title | C1: Written by | D1: Linkedin | E1: Twitter | F1: Instagram | G1: Facebook | H1: website | I1: New Links | J1: old Website linkHow to Convert Legacy Training Content to Modern eLearning | K1: Indexation | L1: Qoura | M1: Reddit | N1: Facbook | O1: Instagram | P1: LinkedIn | Q1: Pinterest | R1: Dev.to | S1: Medium | T1: Tumblr | U1: Substack | Z1: indexation | AC1: Workflow Status | AD1: Priority | AE1: Owner | AF1: Due Date | AG1: Published URL | AH1: Team Support Needed | AI1: Community Sharing Needed | AJ1: Community / Post Link | AK1: Next Action | AL1: Days to Due | AM1: Health | AN1: Last Updated | AO1: Management Notes | AP1: =HYPERLINK("#'Guide'!A1","Open Guide") -> Open Guide
A2: 46023 | B2: Time Management and Productivity Skills students can Master 2025 | C2: C5 | D2: Yes | H2: Yes | J2: https://theeduassist.com/wp-admin/post.php?post=1648&action=edit | Z2: Web content writing | AC2: =IF($B2="","",IF(AND($AB2="Done",$H2="Yes"),"Published",IF($AB2="Done","Ready to Publish","In Progress"))) -> In Progress | AK2: =IF($B2="","",IF($AC2<>"Done","Complete content audit",IF($H2<>"Yes","Publish on website",IF($AH2="Yes","Log and assign team support",IF($AI2="Yes","Share in a relevant community","Complete"))))) -> Complete content audit | AL2: =IF(OR($B2="",$AF2=""),"",INT($AF2-TODAY())) | AM2: =IF($B2="","",IF($AC2="Published","Complete",IF($AL2="","No Deadline",IF($AL2<0,"Overdue",IF($AL2<=2,"Due Soon","On Track"))))) -> No Deadline
A3: 46024 | B3: Complete Guide to SaaS Curriculum Development and Training Best Practices | C3: C5 | D3: Yes | H3: Yes | J3: https://theeduassist.com/wp-admin/post.php?post=1703&action=edit | Z3: Introduction to MOOCs | AC3: =IF($B3="","",IF(AND($AB3="Done",$H3="Yes"),"Published",IF($AB3="Done","Ready to Publish","In Progress"))) -> In Progress | AK3: =IF($B3="","",IF(#REF!<>"Done","Complete content audit",IF($H3<>"Yes","Publish on website",IF($AH3="Yes","Log and assign team support",IF($AI3="Yes","Share in a relevant community","Complete"))))) -> #REF! | AL3: =IF(OR($B3="",$AF3=""),"",INT($AF3-TODAY())) | AM3: =IF($B3="","",IF($AC3="Published","Complete",IF($AL3="","No Deadline",IF($AL3<0,"Overdue",IF($AL3<=2,"Due Soon","On Track"))))) -> No Deadline
A4: 46024 | B4: Continuing Education Creation: How to Develop Effective Programs for Professionals 2026 | C4: C5 | D4: Yes | H4: Yes | J4: https://theeduassist.com/wp-admin/post.php?post=1723&action=edit | AC4: =IF($B4="","",IF(AND($AB4="Done",$H4="Yes"),"Published",IF($AB4="Done","Ready to Publish","In Progress"))) -> In Progress | AK4: =IF($B4="","",IF(#REF!<>"Done","Complete content audit",IF($H4<>"Yes","Publish on website",IF($AH4="Yes","Log and assign team support",IF($AI4="Yes","Share in a relevant community","Complete"))))) -> #REF! | AL4: =IF(OR($B4="",$AF4=""),"",INT($AF4-TODAY())) | AM4: =IF($B4="","",IF($AC4="Published","Complete",IF($AL4="","No Deadline",IF($AL4<0,"Overdue",IF($AL4<=2,"Due Soon","On Track"))))) -> No Deadline
A5: 46025 | B5: Instructional Design in Action: Practical Solutions for Learner Problems | C5: C5 | D5: Yes | H5: Yes | J5: https://theeduassist.com/wp-admin/post.php?post=1885&action=edit | Z5: Content Brief Structure | AC5: =IF($B5="","",IF(AND($AB5="Done",$H5="Yes"),"Published",IF($AB5="Done","Ready to Publish","In Progress"))) -> In Progress | AK5: =IF($B5="","",IF(#REF!<>"Done","Complete content audit",IF($H5<>"Yes","Publish on website",IF($AH5="Yes","Log and assign team support",IF($AI5="Yes","Share in a relevant community","Complete"))))) -> #REF! | AL5: =IF(OR($B5="",$AF5=""),"",INT($AF5-TODAY())) | AM5: =IF($B5="","",IF($AC5="Published","Complete",IF($AL5="","No Deadline",IF($AL5<0,"Overdue",IF($AL5<=2,"Due Soon","On Track"))))) -> No Deadline
A6: 46025 | B6: Thinkific Course Creation and LMS Management: How to Create Online Courses 2026 | C6: C5 | D6: Yes | H6: Yes | J6: https://theeduassist.com/wp-admin/post.php?post=1940&action=edit | L6: https://qr.ae/pFIFOi & https://qr.ae/pFGVFp | M6: https://www.reddit.com/r/elearning/comments/1sm9npn/comment/oi6cc1h/?utm_source=share&utm_medium=web3x&utm_name=web3xcss&utm_term=1&utm_content=share_button | Z6: Content Brief Structure | AC6: =IF($B6="","",IF(AND($AB6="Done",$H6="Yes"),"Published",IF($AB6="Done","Ready to Publish","In Progress"))) -> In Progress | AK6: =IF($B6="","",IF(#REF!<>"Done","Complete content audit",IF($H6<>"Yes","Publish on website",IF($AH6="Yes","Log and assign team support",IF($AI6="Yes","Share in a relevant community","Complete"))))) -> #REF! | AL6: =IF(OR($B6="",$AF6=""),"",INT($AF6-TODAY())) | AM6: =IF($B6="","",IF($AC6="Published","Complete",IF($AL6="","No Deadline",IF($AL6<0,"Overdue",IF($AL6<=2,"Due Soon","On Track"))))) -> No Deadline
A7: 46028 | B7: AI Insights Powering Skills-Based Learning and Professional Growth in 2026 | C7: C5 | D7: Yes | H7: Yes | J7: https://theeduassist.com/wp-admin/post.php?post=2164&action=edit | M7: https://www.reddit.com/r/edtech/comments/1sh9cyz/comment/og3ucfx/?utm_source=share&utm_medium=web3x&utm_name=web3xcss&utm_term=1&utm_content=share_button | Z7: Content Brief Structure | AC7: =IF($B7="","",IF(AND($AB7="Done",$H7="Yes"),"Published",IF($AB7="Done","Ready to Publish","In Progress"))) -> In Progress | AK7: =IF($B7="","",IF(#REF!<>"Done","Complete content audit",IF($H7<>"Yes","Publish on website",IF($AH7="Yes","Log and assign team support",IF($AI7="Yes","Share in a relevant community","Complete"))))) -> #REF! | AL7: =IF(OR($B7="",$AF7=""),"",INT($AF7-TODAY())) | AM7: =IF($B7="","",IF($AC7="Published","Complete",IF($AL7="","No Deadline",IF($AL7<0,"Overdue",IF($AL7<=2,"Due Soon","On Track"))))) -> No Deadline
A8: 46029 | B8: Udemy Made Simple: How the Platform Works for Learners and Instructors | C8: C5 | D8: Yes | H8: Yes | J8: https://theeduassist.com/wp-admin/post.php?post=2241&action=edit | L8: https://qr.ae/pFhUsp | Z8: Web content writing | AC8: =IF($B8="","",IF(AND($AB8="Done",$H8="Yes"),"Published",IF($AB8="Done","Ready to Publish","In Progress"))) -> In Progress | AK8: =IF($B8="","",IF(#REF!<>"Done","Complete content audit",IF($H8<>"Yes","Publish on website",IF($AH8="Yes","Log and assign team support",IF($AI8="Yes","Share in a relevant community","Complete"))))) -> #REF! | AL8: =IF(OR($B8="",$AF8=""),"",INT($AF8-TODAY())) | AM8: =IF($B8="","",IF($AC8="Published","Complete",IF($AL8="","No Deadline",IF($AL8<0,"Overdue",IF($AL8<=2,"Due Soon","On Track"))))) -> No Deadline
A9: 46029 | B9: Strategic Digital Product Architecture for Wealth Systems: A Simple Guide | C9: C5 | D9: Yes | H9: Yes | J9: https://theeduassist.com/wp-admin/post.php?post=2245&action=edit | Z9: Content Brief Structure | AC9: =IF($B9="","",IF(AND($AB9="Done",$H9="Yes"),"Published",IF($AB9="Done","Ready to Publish","In Progress"))) -> In Progress | AK9: =IF($B9="","",IF(#REF!<>"Done","Complete content audit",IF($H9<>"Yes","Publish on website",IF($AH9="Yes","Log and assign team support",IF($AI9="Yes","Share in a relevant community","Complete"))))) -> #REF! | AL9: =IF(OR($B9="",$AF9=""),"",INT($AF9-TODAY())) | AM9: =IF($B9="","",IF($AC9="Published","Complete",IF($AL9="","No Deadline",IF($AL9<0,"Overdue",IF($AL9<=2,"Due Soon","On Track"))))) -> No Deadline
A10: 46030 | B10: A Practical 2026 Guide in Using Skool for Real Estate Lending Sales Training | C10: C5 | D10: Yes | H10: Yes | J10: https://theeduassist.com/wp-admin/post.php?post=4021&action=edit | AC10: =IF($B10="","",IF(AND($AB10="Done",$H10="Yes"),"Published",IF($AB10="Done","Ready to Publish","In Progress"))) -> In Progress | AK10: =IF($B10="","",IF(#REF!<>"Done","Complete content audit",IF($H10<>"Yes","Publish on website",IF($AH10="Yes","Log and assign team support",IF($AI10="Yes","Share in a relevant community","Complete"))))) -> #REF! | AL10: =IF(OR($B10="",$AF10=""),"",INT($AF10-TODAY())) | AM10: =IF($B10="","",IF($AC10="Published","Complete",IF($AL10="","No Deadline",IF($AL10<0,"Overdue",IF($AL10<=2,"Due Soon","On Track"))))) -> No Deadline
A11: 46031 | B11: Why Learners Skip Pop-Ups and How Better Design Changes That | C11: C5 | D11: Yes | H11: Yes | J11: https://theeduassist.com/wp-admin/post.php?post=2324&action=edit | AC11: =IF($B11="","",IF(AND($AB11="Done",$H11="Yes"),"Published",IF($AB11="Done","Ready to Publish","In Progress"))) -> In Progress | AK11: =IF($B11="","",IF(#REF!<>"Done","Complete content audit",IF($H11<>"Yes","Publish on website",IF($AH11="Yes","Log and assign team support",IF($AI11="Yes","Share in a relevant community","Complete"))))) -> #REF! | AL11: =IF(OR($B11="",$AF11=""),"",INT($AF11-TODAY())) | AM11: =IF($B11="","",IF($AC11="Published","Complete",IF($AL11="","No Deadline",IF($AL11<0,"Overdue",IF($AL11<=2,"Due Soon","On Track"))))) -> No Deadline
A12: 46031 | B12: MOOCs and IT Education: A Practical Guide for Learners in 2026 | C12: C5 | D12: Yes | H12: Yes | J12: https://theeduassist.com/wp-admin/post.php?post=2328&action=edit | AC12: =IF($B12="","",IF(AND($AB12="Done",$H12="Yes"),"Published",IF($AB12="Done","Ready to Publish","In Progress"))) -> In Progress | AK12: =IF($B12="","",IF(#REF!<>"Done","Complete content audit",IF($H12<>"Yes","Publish on website",IF($AH12="Yes","Log and assign team support",IF($AI12="Yes","Share in a relevant community","Complete"))))) -> #REF! | AL12: =IF(OR($B12="",$AF12=""),"",INT($AF12-TODAY())) | AM12: =IF($B12="","",IF($AC12="Published","Complete",IF($AL12="","No Deadline",IF($AL12<0,"Overdue",IF($AL12<=2,"Due Soon","On Track"))))) -> No Deadline
A13: 46032 | B13: How to Apply SETA Standards in Digital and Blended Learning Environments | C13: C5 | D13: Yes | H13: Yes | J13: https://theeduassist.com/wp-admin/post.php?post=2417&action=edit | AC13: =IF($B13="","",IF(AND($AB13="Done",$H13="Yes"),"Published",IF($AB13="Done","Ready to Publish","In Progress"))) -> In Progress | AK13: =IF($B13="","",IF(#REF!<>"Done","Complete content audit",IF($H13<>"Yes","Publish on website",IF($AH13="Yes","Log and assign team support",IF($AI13="Yes","Share in a relevant community","Complete"))))) -> #REF! | AL13: =IF(OR($B13="",$AF13=""),"",INT($AF13-TODAY())) | AM13: =IF($B13="","",IF($AC13="Published","Complete",IF($AL13="","No Deadline",IF($AL13<0,"Overdue",IF($AL13<=2,"Due Soon","On Track"))))) -> No Deadline
A14: 46032 | B14: Education Is The Key Of Success, its future 2026 | C14: C5 | D14: Yes | H14: Yes | J14: https://theeduassist.com/wp-admin/post.php?post=2423&action=edit | AC14: =IF($B14="","",IF(AND($AB14="Done",$H14="Yes"),"Published",IF($AB14="Done","Ready to Publish","In Progress"))) -> In Progress | AK14: =IF($B14="","",IF(#REF!<>"Done","Complete content audit",IF($H14<>"Yes","Publish on website",IF($AH14="Yes","Log and assign team support",IF($AI14="Yes","Share in a relevant community","Complete"))))) -> #REF! | AL14: =IF(OR($B14="",$AF14=""),"",INT($AF14-TODAY())) | AM14: =IF($B14="","",IF($AC14="Published","Complete",IF($AL14="","No Deadline",IF($AL14<0,"Overdue",IF($AL14<=2,"Due Soon","On Track"))))) -> No Deadline
A15: 46034 | B15: Gamification 2026: How to Boost Engagement, Learning, and Productivity | C15: C5 | D15: Yes | H15: Yes | J15: https://theeduassist.com/wp-admin/post.php?post=2482&action=edit | L15: https://qr.ae/pF25dm | AC15: =IF($B15="","",IF(AND($AB15="Done",$H15="Yes"),"Published",IF($AB15="Done","Ready to Publish","In Progress"))) -> In Progress | AK15: =IF($B15="","",IF(#REF!<>"Done","Complete content audit",IF($H15<>"Yes","Publish on website",IF($AH15="Yes","Log and assign team support",IF($AI15="Yes","Share in a relevant community","Complete"))))) -> #REF! | AL15: =IF(OR($B15="",$AF15=""),"",INT($AF15-TODAY())) | AM15: =IF($B15="","",IF($AC15="Published","Complete",IF($AL15="","No Deadline",IF($AL15<0,"Overdue",IF($AL15<=2,"Due Soon","On Track"))))) -> No Deadline
A16: 46034 | B16: What Are Terminal Learning Objectives? | C16: C5 | D16: Yes | H16: Yes | J16: https://theeduassist.com/wp-admin/post.php?post=2501&action=edit | AC16: =IF($B16="","",IF(AND($AB16="Done",$H16="Yes"),"Published",IF($AB16="Done","Ready to Publish","In Progress"))) -> In Progress | AK16: =IF($B16="","",IF(#REF!<>"Done","Complete content audit",IF($H16<>"Yes","Publish on website",IF($AH16="Yes","Log and assign team support",IF($AI16="Yes","Share in a relevant community","Complete"))))) -> #REF! | AL16: =IF(OR($B16="",$AF16=""),"",INT($AF16-TODAY())) | AM16: =IF($B16="","",IF($AC16="Published","Complete",IF($AL16="","No Deadline",IF($AL16<0,"Overdue",IF($AL16<=2,"Due Soon","On Track"))))) -> No Deadline
A17: 46035 | B17: How to Promote Your Online Course by Using Teachability Principles 2026 | C17: C5 | D17: Yes | H17: Yes | J17: https://theeduassist.com/wp-admin/post.php?post=2514&action=edit | L17: https://qr.ae/pFTUpe | AC17: =IF($B17="","",IF(AND($AB17="Done",$H17="Yes"),"Published",IF($AB17="Done","Ready to Publish","In Progress"))) -> In Progress | AK17: =IF($B17="","",IF(#REF!<>"Done","Complete content audit",IF($H17<>"Yes","Publish on website",IF($AH17="Yes","Log and assign team support",IF($AI17="Yes","Share in a relevant community","Complete"))))) -> #REF! | AL17: =IF(OR($B17="",$AF17=""),"",INT($AF17-TODAY())) | AM17: =IF($B17="","",IF($AC17="Published","Complete",IF($AL17="","No Deadline",IF($AL17<0,"Overdue",IF($AL17<=2,"Due Soon","On Track"))))) -> No Deadline
A18: 46035 | B18: Teachability: How to Improve Learning and Retention in Education | C18: C5 | D18: Yes | H18: Yes | J18: https://theeduassist.com/blog/teachability/ | AC18: =IF($B18="","",IF(AND($AB18="Done",$H18="Yes"),"Published",IF($AB18="Done","Ready to Publish","In Progress"))) -> In Progress | AK18: =IF($B18="","",IF(#REF!<>"Done","Complete content audit",IF($H18<>"Yes","Publish on website",IF($AH18="Yes","Log and assign team support",IF($AI18="Yes","Share in a relevant community","Complete"))))) -> #REF! | AL18: =IF(OR($B18="",$AF18=""),"",INT($AF18-TODAY())) | AM18: =IF($B18="","",IF($AC18="Published","Complete",IF($AL18="","No Deadline",IF($AL18<0,"Overdue",IF($AL18<=2,"Due Soon","On Track"))))) -> No Deadline
A19: 46036 | B19: AI-Driven Online Learning: From Content Creation to Skill Mastery | C19: C5 | D19: Yes | H19: Yes | J19: https://theeduassist.com/wp-admin/post.php?post=2588&action=edit | AC19: =IF($B19="","",IF(AND($AB19="Done",$H19="Yes"),"Published",IF($AB19="Done","Ready to Publish","In Progress"))) -> In Progress | AK19: =IF($B19="","",IF(#REF!<>"Done","Complete content audit",IF($H19<>"Yes","Publish on website",IF($AH19="Yes","Log and assign team support",IF($AI19="Yes","Share in a relevant community","Complete"))))) -> #REF! | AL19: =IF(OR($B19="",$AF19=""),"",INT($AF19-TODAY())) | AM19: =IF($B19="","",IF($AC19="Published","Complete",IF($AL19="","No Deadline",IF($AL19<0,"Overdue",IF($AL19<=2,"Due Soon","On Track"))))) -> No Deadline
A20: 46036 | B20: eLearning 2026: How Technology is Reshaping Education | C20: C5 | D20: Yes | H20: Yes | J20: https://theeduassist.com/wp-admin/post.php?post=2620&action=edit | AC20: =IF($B20="","",IF(AND($AB20="Done",$H20="Yes"),"Published",IF($AB20="Done","Ready to Publish","In Progress"))) -> In Progress | AK20: =IF($B20="","",IF(#REF!<>"Done","Complete content audit",IF($H20<>"Yes","Publish on website",IF($AH20="Yes","Log and assign team support",IF($AI20="Yes","Share in a relevant community","Complete"))))) -> #REF! | AL20: =IF(OR($B20="",$AF20=""),"",INT($AF20-TODAY())) | AM20: =IF($B20="","",IF($AC20="Published","Complete",IF($AL20="","No Deadline",IF($AL20<0,"Overdue",IF($AL20<=2,"Due Soon","On Track"))))) -> No Deadline
A21: 46037 | B21: Go High Level for Education Businesses: What Actually Works | C21: C5 | D21: Yes | H21: Yes | J21: https://theeduassist.com/wp-admin/post.php?post=2628&action=edit | AC21: =IF($B21="","",IF(AND($AB21="Done",$H21="Yes"),"Published",IF($AB21="Done","Ready to Publish","In Progress"))) -> In Progress | AK21: =IF($B21="","",IF(#REF!<>"Done","Complete content audit",IF($H21<>"Yes","Publish on website",IF($AH21="Yes","Log and assign team support",IF($AI21="Yes","Share in a relevant community","Complete"))))) -> #REF! | AL21: =IF(OR($B21="",$AF21=""),"",INT($AF21-TODAY())) | AM21: =IF($B21="","",IF($AC21="Published","Complete",IF($AL21="","No Deadline",IF($AL21<0,"Overdue",IF($AL21<=2,"Due Soon","On Track"))))) -> No Deadline
A22: 46038 | B22: What Is a Personal Learning Environment? And Why It Really Helps You Learn | C22: C5 | D22: Yes | H22: Yes | J22: https://theeduassist.com/wp-admin/post.php?post=2678&action=edit | AC22: =IF($B22="","",IF(AND($AB22="Done",$H22="Yes"),"Published",IF($AB22="Done","Ready to Publish","In Progress"))) -> In Progress | AK22: =IF($B22="","",IF(#REF!<>"Done","Complete content audit",IF($H22<>"Yes","Publish on website",IF($AH22="Yes","Log and assign team support",IF($AI22="Yes","Share in a relevant community","Complete"))))) -> #REF! | AL22: =IF(OR($B22="",$AF22=""),"",INT($AF22-TODAY())) | AM22: =IF($B22="","",IF($AC22="Published","Complete",IF($AL22="","No Deadline",IF($AL22<0,"Overdue",IF($AL22<=2,"Due Soon","On Track"))))) -> No Deadline
A23: 46039 | B23: How Customized Safety Training Reduces Risks in Oil & Gas | C23: C5 | D23: Yes | H23: Yes | J23: https://theeduassist.com/blog/ai-customized-safety-training/ | AC23: =IF($B23="","",IF(AND($AB23="Done",$H23="Yes"),"Published",IF($AB23="Done","Ready to Publish","In Progress"))) -> In Progress | AK23: =IF($B23="","",IF(#REF!<>"Done","Complete content audit",IF($H23<>"Yes","Publish on website",IF($AH23="Yes","Log and assign team support",IF($AI23="Yes","Share in a relevant community","Complete"))))) -> #REF! | AL23: =IF(OR($B23="",$AF23=""),"",INT($AF23-TODAY())) | AM23: =IF($B23="","",IF($AC23="Published","Complete",IF($AL23="","No Deadline",IF($AL23<0,"Overdue",IF($AL23<=2,"Due Soon","On Track"))))) -> No Deadline
A24: 46049 | B24: How FERPA Protects Student Privacy | C24: C5 | D24: Yes | H24: Yes | J24: https://theeduassist.com/blog/what-is-ferpa/ | AC24: =IF($B24="","",IF(AND($AB24="Done",$H24="Yes"),"Published",IF($AB24="Done","Ready to Publish","In Progress"))) -> In Progress | AK24: =IF($B24="","",IF(#REF!<>"Done","Complete content audit",IF($H24<>"Yes","Publish on website",IF($AH24="Yes","Log and assign team support",IF($AI24="Yes","Share in a relevant community","Complete"))))) -> #REF! | AL24: =IF(OR($B24="",$AF24=""),"",INT($AF24-TODAY())) | AM24: =IF($B24="","",IF($AC24="Published","Complete",IF($AL24="","No Deadline",IF($AL24<0,"Overdue",IF($AL24<=2,"Due Soon","On Track"))))) -> No Deadline
A25: 46050 | B25: Instructional Design Services for Custom eLearning Development | C25: C5 | D25: Yes | H25: Yes | J25: https://theeduassist.com/wp-admin/post.php?post=2992&action=edit | AC25: =IF($B25="","",IF(AND($AB25="Done",$H25="Yes"),"Published",IF($AB25="Done","Ready to Publish","In Progress"))) -> In Progress | AK25: =IF($B25="","",IF(#REF!<>"Done","Complete content audit",IF($H25<>"Yes","Publish on website",IF($AH25="Yes","Log and assign team support",IF($AI25="Yes","Share in a relevant community","Complete"))))) -> #REF! | AL25: =IF(OR($B25="",$AF25=""),"",INT($AF25-TODAY())) | AM25: =IF($B25="","",IF($AC25="Published","Complete",IF($AL25="","No Deadline",IF($AL25<0,"Overdue",IF($AL25<=2,"Due Soon","On Track"))))) -> No Deadline
A26: 46051 | B26: A Practical Guide to Planning and Development Training | C26: C5 | D26: Yes | H26: Yes | J26: https://theeduassist.com/wp-admin/post.php?post=3144&action=edit | AC26: =IF($B26="","",IF(AND($AB26="Done",$H26="Yes"),"Published",IF($AB26="Done","Ready to Publish","In Progress"))) -> In Progress | AK26: =IF($B26="","",IF(#REF!<>"Done","Complete content audit",IF($H26<>"Yes","Publish on website",IF($AH26="Yes","Log and assign team support",IF($AI26="Yes","Share in a relevant community","Complete"))))) -> #REF! | AL26: =IF(OR($B26="",$AF26=""),"",INT($AF26-TODAY())) | AM26: =IF($B26="","",IF($AC26="Published","Complete",IF($AL26="","No Deadline",IF($AL26<0,"Overdue",IF($AL26<=2,"Due Soon","On Track"))))) -> No Deadline
A27: 46053 | B27: What Are Terminal Learning Objectives? | C27: C5 | D27: Yes | H27: Yes | J27: https://theeduassist.com/wp-admin/post.php?post=3252&action=edit | AC27: =IF($B27="","",IF(AND($AB27="Done",$H27="Yes"),"Published",IF($AB27="Done","Ready to Publish","In Progress"))) -> In Progress | AK27: =IF($B27="","",IF(#REF!<>"Done","Complete content audit",IF($H27<>"Yes","Publish on website",IF($AH27="Yes","Log and assign team support",IF($AI27="Yes","Share in a relevant community","Complete"))))) -> #REF! | AL27: =IF(OR($B27="",$AF27=""),"",INT($AF27-TODAY())) | AM27: =IF($B27="","",IF($AC27="Published","Complete",IF($AL27="","No Deadline",IF($AL27<0,"Overdue",IF($AL27<=2,"Due Soon","On Track"))))) -> No Deadline
A28: 46054 | C28: C5 | D28: Yes | H28: Yes | J28: https://theeduassist.com/wp-admin/post.php?post=3252&action=edit | AC28: =IF($B28="","",IF(AND($AB28="Done",$H28="Yes"),"Published",IF($AB28="Done","Ready to Publish","In Progress"))) | AK28: =IF($B28="","",IF(#REF!<>"Done","Complete content audit",IF($H28<>"Yes","Publish on website",IF($AH28="Yes","Log and assign team support",IF($AI28="Yes","Share in a relevant community","Complete"))))) | AL28: =IF(OR($B28="",$AF28=""),"",INT($AF28-TODAY())) | AM28: =IF($B28="","",IF($AC28="Published","Complete",IF($AL28="","No Deadline",IF($AL28<0,"Overdue",IF($AL28<=2,"Due Soon","On Track")))))
A29: 46055 | B29: Kajabi Course Design Explained | C29: C5 | D29: Yes | H29: Yes | J29: https://theeduassist.com/wp-admin/post.php?post=3353&action=edit | L29: https://qr.ae/pFIwwD https://qr.ae/pFIxPX | AC29: =IF($B29="","",IF(AND($AB29="Done",$H29="Yes"),"Published",IF($AB29="Done","Ready to Publish","In Progress"))) -> In Progress | AK29: =IF($B29="","",IF(#REF!<>"Done","Complete content audit",IF($H29<>"Yes","Publish on website",IF($AH29="Yes","Log and assign team support",IF($AI29="Yes","Share in a relevant community","Complete"))))) -> #REF! | AL29: =IF(OR($B29="",$AF29=""),"",INT($AF29-TODAY())) | AM29: =IF($B29="","",IF($AC29="Published","Complete",IF($AL29="","No Deadline",IF($AL29<0,"Overdue",IF($AL29<=2,"Due Soon","On Track"))))) -> No Deadline
A30: 46056 | B30: What Is a Curriculum Development Centre? | C30: C5 | D30: Yes | H30: Yes | J30: https://theeduassist.com/wp-admin/post.php?post=3430&action=edit | AC30: =IF($B30="","",IF(AND($AB30="Done",$H30="Yes"),"Published",IF($AB30="Done","Ready to Publish","In Progress"))) -> In Progress | AK30: =IF($B30="","",IF(#REF!<>"Done","Complete content audit",IF($H30<>"Yes","Publish on website",IF($AH30="Yes","Log and assign team support",IF($AI30="Yes","Share in a relevant community","Complete"))))) -> #REF! | AL30: =IF(OR($B30="",$AF30=""),"",INT($AF30-TODAY())) | AM30: =IF($B30="","",IF($AC30="Published","Complete",IF($AL30="","No Deadline",IF($AL30<0,"Overdue",IF($AL30<=2,"Due Soon","On Track"))))) -> No Deadline
A31: 46058 | B31: Why Learning Is the Strongest Skill You Can Build | C31: C5 | D31: Yes | H31: Yes | J31: https://theeduassist.com/wp-admin/post.php?post=3496&action=edit | AC31: =IF($B31="","",IF(AND($AB31="Done",$H31="Yes"),"Published",IF($AB31="Done","Ready to Publish","In Progress"))) -> In Progress | AK31: =IF($B31="","",IF(#REF!<>"Done","Complete content audit",IF($H31<>"Yes","Publish on website",IF($AH31="Yes","Log and assign team support",IF($AI31="Yes","Share in a relevant community","Complete"))))) -> #REF! | AL31: =IF(OR($B31="",$AF31=""),"",INT($AF31-TODAY())) | AM31: =IF($B31="","",IF($AC31="Published","Complete",IF($AL31="","No Deadline",IF($AL31<0,"Overdue",IF($AL31<=2,"Due Soon","On Track"))))) -> No Deadline
A32: 46059 | B32: Why Kajabi Works Better Than Multiple Tools for Coaching Businesses | C32: C5 | D32: Yes | H32: Yes | J32: https://theeduassist.com/wp-admin/post.php?post=3506&action=edit | L32: https://qr.ae/pFIFOi & https://qr.ae/pFnco4 | AC32: =IF($B32="","",IF(AND($AB32="Done",$H32="Yes"),"Published",IF($AB32="Done","Ready to Publish","In Progress"))) -> In Progress | AK32: =IF($B32="","",IF(#REF!<>"Done","Complete content audit",IF($H32<>"Yes","Publish on website",IF($AH32="Yes","Log and assign team support",IF($AI32="Yes","Share in a relevant community","Complete"))))) -> #REF! | AL32: =IF(OR($B32="",$AF32=""),"",INT($AF32-TODAY())) | AM32: =IF($B32="","",IF($AC32="Published","Complete",IF($AL32="","No Deadline",IF($AL32<0,"Overdue",IF($AL32<=2,"Due Soon","On Track"))))) -> No Deadline
A33: 46060 | B33: The Essential Guide to AI-Generated Course Quality 2026 | C33: C5 | D33: Yes | H33: Yes | J33: https://theeduassist.com/wp-admin/post.php?post=3545&action=edit | M33: https://www.reddit.com/r/Learning/comments/1sfd4d0/comment/of2xs3o/?utm_source=share&utm_medium=web3x&utm_name=web3xcss&utm_term=1&utm_content=share_button | AC33: =IF($B33="","",IF(AND($AB33="Done",$H33="Yes"),"Published",IF($AB33="Done","Ready to Publish","In Progress"))) -> In Progress | AK33: =IF($B33="","",IF(#REF!<>"Done","Complete content audit",IF($H33<>"Yes","Publish on website",IF($AH33="Yes","Log and assign team support",IF($AI33="Yes","Share in a relevant community","Complete"))))) -> #REF! | AL33: =IF(OR($B33="",$AF33=""),"",INT($AF33-TODAY())) | AM33: =IF($B33="","",IF($AC33="Published","Complete",IF($AL33="","No Deadline",IF($AL33<0,"Overdue",IF($AL33<=2,"Due Soon","On Track"))))) -> No Deadline
A34: 46065 | B34: Choosing the Right Authoring Tool: Affordable Alternatives to Articulate Storyline | C34: C5 | D34: Yes | H34: Yes | J34: https://theeduassist.com/wp-admin/post.php?post=3711&action=edit | L34: https://qr.ae/pFTy9k | AC34: =IF($B34="","",IF(AND($AB34="Done",$H34="Yes"),"Published",IF($AB34="Done","Ready to Publish","In Progress"))) -> In Progress | AK34: =IF($B34="","",IF(#REF!<>"Done","Complete content audit",IF($H34<>"Yes","Publish on website",IF($AH34="Yes","Log and assign team support",IF($AI34="Yes","Share in a relevant community","Complete"))))) -> #REF! | AL34: =IF(OR($B34="",$AF34=""),"",INT($AF34-TODAY())) | AM34: =IF($B34="","",IF($AC34="Published","Complete",IF($AL34="","No Deadline",IF($AL34<0,"Overdue",IF($AL34<=2,"Due Soon","On Track"))))) -> No Deadline
A35: 46069 | B35: How to Overcome LMS Course Editing | C35: C5 | D35: Yes | H35: Yes | J35: https://theeduassist.com/wp-admin/post.php?post=3895&action=edit | AC35: =IF($B35="","",IF(AND($AB35="Done",$H35="Yes"),"Published",IF($AB35="Done","Ready to Publish","In Progress"))) -> In Progress | AK35: =IF($B35="","",IF(#REF!<>"Done","Complete content audit",IF($H35<>"Yes","Publish on website",IF($AH35="Yes","Log and assign team support",IF($AI35="Yes","Share in a relevant community","Complete"))))) -> #REF! | AL35: =IF(OR($B35="",$AF35=""),"",INT($AF35-TODAY())) | AM35: =IF($B35="","",IF($AC35="Published","Complete",IF($AL35="","No Deadline",IF($AL35<0,"Overdue",IF($AL35<=2,"Due Soon","On Track"))))) -> No Deadline
A36: 46070 | B36: Training Coordination Made Easy | C36: C5 | D36: Yes | H36: Yes | J36: https://theeduassist.com/wp-admin/post.php?post=3914&action=edit | AC36: =IF($B36="","",IF(AND($AB36="Done",$H36="Yes"),"Published",IF($AB36="Done","Ready to Publish","In Progress"))) -> In Progress | AK36: =IF($B36="","",IF(#REF!<>"Done","Complete content audit",IF($H36<>"Yes","Publish on website",IF($AH36="Yes","Log and assign team support",IF($AI36="Yes","Share in a relevant community","Complete"))))) -> #REF! | AL36: =IF(OR($B36="",$AF36=""),"",INT($AF36-TODAY())) | AM36: =IF($B36="","",IF($AC36="Published","Complete",IF($AL36="","No Deadline",IF($AL36<0,"Overdue",IF($AL36<=2,"Due Soon","On Track"))))) -> No Deadline
A37: 46071 | B37: Beyond Gamification: How to Make Interactive Learning Truly Effective | C37: C5 | H37: Yes | J37: https://theeduassist.com/wp-admin/post.php?post=3921&action=edit | AC37: =IF($B37="","",IF(AND($AB37="Done",$H37="Yes"),"Published",IF($AB37="Done","Ready to Publish","In Progress"))) -> In Progress | AK37: =IF($B37="","",IF(#REF!<>"Done","Complete content audit",IF($H37<>"Yes","Publish on website",IF($AH37="Yes","Log and assign team support",IF($AI37="Yes","Share in a relevant community","Complete"))))) -> #REF! | AL37: =IF(OR($B37="",$AF37=""),"",INT($AF37-TODAY())) | AM37: =IF($B37="","",IF($AC37="Published","Complete",IF($AL37="","No Deadline",IF($AL37<0,"Overdue",IF($AL37<=2,"Due Soon","On Track"))))) -> No Deadline
A38: 46071 | B38: Quest 3 for Sim Racing: Can It Be Made Reliable? | C38: C5 | H38: Yes | J38: https://theeduassist.com/wp-admin/post.php?post=3928&action=edit | AC38: =IF($B38="","",IF(AND($AB38="Done",$H38="Yes"),"Published",IF($AB38="Done","Ready to Publish","In Progress"))) -> In Progress | AK38: =IF($B38="","",IF(#REF!<>"Done","Complete content audit",IF($H38<>"Yes","Publish on website",IF($AH38="Yes","Log and assign team support",IF($AI38="Yes","Share in a relevant community","Complete"))))) -> #REF! | AL38: =IF(OR($B38="",$AF38=""),"",INT($AF38-TODAY())) | AM38: =IF($B38="","",IF($AC38="Published","Complete",IF($AL38="","No Deadline",IF($AL38<0,"Overdue",IF($AL38<=2,"Due Soon","On Track"))))) -> No Deadline
A39: 46072 | B39: Instructional Design Checklist: Make Your Online Courses More Engaging | C39: C5 | H39: Yes | J39: https://theeduassist.com/wp-admin/post.php?post=3939&action=edit | AC39: =IF($B39="","",IF(AND($AB39="Done",$H39="Yes"),"Published",IF($AB39="Done","Ready to Publish","In Progress"))) -> In Progress | AK39: =IF($B39="","",IF(#REF!<>"Done","Complete content audit",IF($H39<>"Yes","Publish on website",IF($AH39="Yes","Log and assign team support",IF($AI39="Yes","Share in a relevant community","Complete"))))) -> #REF! | AL39: =IF(OR($B39="",$AF39=""),"",INT($AF39-TODAY())) | AM39: =IF($B39="","",IF($AC39="Published","Complete",IF($AL39="","No Deadline",IF($AL39<0,"Overdue",IF($AL39<=2,"Due Soon","On Track"))))) -> No Deadline
A40: 46072 | B40: AI + Microlearning: The Ultimate Formula for Corporate training 2026 - | C40: C5 | H40: Yes | J40: https://theeduassist.com/wp-admin/post.php?post=3990&action=edit | AC40: =IF($B40="","",IF(AND($AB40="Done",$H40="Yes"),"Published",IF($AB40="Done","Ready to Publish","In Progress"))) -> In Progress | AK40: =IF($B40="","",IF(#REF!<>"Done","Complete content audit",IF($H40<>"Yes","Publish on website",IF($AH40="Yes","Log and assign team support",IF($AI40="Yes","Share in a relevant community","Complete"))))) -> #REF! | AL40: =IF(OR($B40="",$AF40=""),"",INT($AF40-TODAY())) | AM40: =IF($B40="","",IF($AC40="Published","Complete",IF($AL40="","No Deadline",IF($AL40<0,"Overdue",IF($AL40<=2,"Due Soon","On Track"))))) -> No Deadline
...

Sheet Kajabi service pages and Kajabi
R1: Kajabi Tree Keywords and FAQ's | AG1: =HYPERLINK("#'Guide'!A1","Open Guide") -> Open Guide
A3: Kajabi Service Pages Keywords, Titles, Description. | R3: Page | S3: KEYWORD | T3: VOLUME | U3: GLOBAL VOLUME | V3: DIFFICULTY | W3: INTENT | X3: TARGETED PAGE | Y3: WORD TYPE | Z3: FAQ's | AD3: FAQ with Answers
R5: Kajabi Course Creation Services | S5: kajabi online course platform​ | T5: 18.1k | U5: 18.1k | V5: 28 | W5: Informational | X5: Kajabi Course Creation Services | Y5: Secondary Keyword | Z5: How do I create a course in Kajabi? | AA5: What is the best platform for course creation? | AD5: All the answers are import from Google. These are for the key idea. Make sure to rewrite the answer that should be appealing before going ahead.
S6: kajabi courses​ | T6: 260 | U6: 640 | V6: 23 | W6: Informational | X6: Kajabi Course Creation Services | Y6: Secondary Keyword | Z6: Is Kajabi good for course creators? | AA6: Do you own your content on Kajabi?
A7: SR NO | B7: TARGETED PAGE | C7: KEYWORD | D7: VOLUME | E7: GLOBAL VOLUME | F7: DIFFICULTY | G7: INTENT | H7: WORD TYPE | I7: Title | J7: Description | K7: Linking page | L7: Keyword in blog | M7: Anchor text | N7: Add Section in blog for link | O7: Backlinks | S7: how to create a course on kajabi | T7: 30 | U7: 30 | X7: Kajabi Course Creation Services | Y7: Secondary Keyword | Z7: Can you sell courses directly through Kajabi? | AD7: FAQ | AE7: Answer | AF7: Topic
A8: 1 | B8: Kajabi Course Setup Service | C8: kajabi online course platform​ | D8: 18.1k | E8: 18.1k | F8: 28 | G8: Informational | H8: Secondary Keyword | S8: how to create a course in kajabi​ | T8: 20 | U8: 100 | X8: Kajabi Course Creation Services | Y8: Secondary Keyword | Z8: Do I need a website if I use Kajabi? | AD8: What types of digital products can I create using Kajabi? | AE8: With Kajabi, you can create a variety of digital products, including online courses, coaching programs, membership sites, digital downloads, and webinars.The platform offers customizable templates to help you design and deliver your content effectively. | AF8: kajabi digital product creation
C9: kajabi online courses | D9: 90 | E9: 310 | G9: Informational | H9: Secondary Keyword | I9: Expert Kajabi Course Setup to Scale Your Business-theEduAssist | J9: Scale your business with pro Kajabi course setup. theEduAssist handles the tech so you can teach. Book your setup call and launch your offer now. | K9: https://theeduassist.com/blog/7-powerful-kajabi-course-creation-services/ | L9: Kajabi Course Creation Services | S9: how to create a kajabi course | T9: 20 | U9: 30 | X9: Kajabi Course Creation Services | Y9: Secondary Keyword | Z9: Is Kajabi difficult to learn? | AD9: Do I need any technical skills to create digital products on Kajabi? | AE9: No, you do not need advanced technical skills to create digital products on Kajabi.The platform is user-friendly and designed for ease of use, with drag-and-drop features and step-by-step guides to help you set up your products and website. | AF9: kajabi digital product creation
C10: kajabi online course setup | G10: Informational | H10: Secondary Keyword | K10: https://theeduassist.com/blog/kajabi-online-course-setup/ | L10: Setting up your online course on Kajabi | M10: professional Kajabi course setup services | S10: kajabi course creation | T10: 20 | U10: 80 | X10: Kajabi Course Creation Services | Y10: Secondary Keyword | Z10: Can someone build my Kajabi course for me? | AD10: Can I sell my digital products on Kajabi? | AE10: es, Kajabi provides built-in sales and marketing tools that allow you to sell your digital products directly from your site.You can set up payment gateways, offer subscription plans, and create marketing funnels to attract and convert customers. | AF10: kajabi digital product creation
C11: setup online course kajabi | G11: Informational | H11: Secondary Keyword | K11: https://theeduassist.com/blog/kajabi-course-design-explained-how-to-create-online-course-in-2026/ | L11: our Kajabi online course | M11: Kajabi course setup experts | S11: Kajabi Course Creation Services | X11: Kajabi Course Creation Services | Y11: Primary Keyword | Z11: Should I hire a Kajabi consultant? | AD11: Is there customer support available if I encounter issues while creating products on Kajabi? | AE11: Yes, Kajabi offers customer support through various channels, including live chat, email, and a comprehensive help center with tutorials and resources.This ensures you can get assistance whenever you need it while creating your digital products. | AF11: kajabi digital product creation
C12: kajabi course setup​ | G12: Informational | H12: Secondary Keyword | K12: https://theeduassist.com/blog/kajabi-course-design/ | L12: Successful Kajabi course creators | M12: Kajabi setup specialists
C13: online course setup​ | D13: 20 | E13: 90 | G13: Informational | H13: Secondary Keyword | K13: https://theeduassist.com/blog/kajabi-drip-course-setup/ | L13: create a Kajabi course | M13: Kajabi course setup strategy | R13: kajabi online course setup | S13: kajabi online course platform​ | T13: 18.1k | U13: 18.1k | V13: 28 | W13: Informational | X13: kajabi online course setup | Y13: Secondary Keyword | Z13: How do I set up an online course in Kajabi? | AA13: How do I create a student-friendly Kajabi course? | AD13: What is Kajabi, and why use it for a membership site? | AE13: Kajabi is an all-in-one platform designed to help you create, market, and sell online courses, memberships, and digital products easily. It’s great for membership sites because it handles everything—from content hosting to payments—all in one place, so you don't need to juggle multiple tools. | AF13: kajabi membership site development
C14: how to create a course on kajabi | D14: 30 | E14: 30 | G14: Informational | H14: Secondary Keyword | S14: kajabi online courses | T14: 90 | U14: 310 | X14: kajabi online course setup | Y14: Secondary Keyword | Z14: How long does Kajabi setup take? | AA14: How do I create a coaching program in Kajabi? | AD14: How do I get started with building a membership site on Kajabi? | AE14: First, sign up for a Kajabi account and choose a plan that fits your needs. Then, you can use their pre-built templates or customize your own site. Set up your membership by creating product categories, uploading your content, and organizing it into member-exclusive access areas. | AF14: kajabi membership site development
C15: how to create a course in kajabi​ | D15: 20 | E15: 100 | G15: Informational | H15: Secondary Keyword | S15: kajabi online course setup | X15: kajabi online course setup | Y15: Primary Keyword | Z15: Is Kajabi hard to set up? | AA15: How do I create a client onboarding course in Kajabi? | AD15: Can I customize the look and feel of my Kajabi membership site? | AE15: Absolutely! Kajabi offers a variety of themes and customization options so you can match your site to your brand. You can change colors, fonts, layout styles, and add your own logo and images to create a professional and unique experience for your members. | AF15: kajabi membership site development
C16: how to create a kajabi course | D16: 20 | E16: 30 | G16: Informational | H16: Secondary Keyword | S16: setup online course kajabi | Z16: What do I need before creating a Kajabi course? | AD16: How do I protect my content so only members can see it? | AE16: Kajabi lets you set access rules easily. When you create your membership product, you choose which content is available to paying members. This way, your videos, downloads, and courses are securely locked behind a login. | AF16: kajabi membership site development
C17: Kajabi Course Setup Service | H17: Primary Keyword | AD17: Do I need technical skills to create a membership site on Kajabi? | AE17: No need to be a tech expert. Kajabi is designed with user-friendliness in mind, offering step-by-step guides and customer support. If you run into any trouble, their help team and community forums are great resources. | AF17: kajabi membership site development
C18: Kajabi services | D18: 40 | E18: 70 | F18: 31 | G18: Navigational | R18: kajabi course design | S18: kajabi course design best practices for engagement | X18: kajabi course design | Y18: Secondary Keyword | Z18: Does Kajabi market your course? | AA18: What is Kajabi and why should I use it for my course? | AD18: Can I track how my membership is performing? | AE18: Definitely. Kajabi provides analytics to monitor member engagement, sales, and other key metrics so you can see what’s working and make improvements where needed. | AF18: kajabi membership site development
S19: kajabi course design | X19: kajabi course design | Y19: Primary Keyword | Z19: How do I start designing a course on Kajabi?
B20: Kajabi Website & Funnel Setup | S20: done for you kajabi course design | X20: kajabi course design | Y20: Secondary Keyword | Z20: Can I customize the look and feel of my course? | AD20: can you upload course modules to kajabi via api​ | AF20: kajabi course upload services
C21: kajabi funnels​ | D21: 20 | E21: 220 | G21: Informational | H21: Primary Keyword | I21: Expert Kajabi Website & Funnel Setup for More Sales | J21: Your Kajabi site should work for you. We build high-converting funnels that boost your revenue. Book your setup call now. | K21: https://theeduassist.com/blog/kajabi-website-funnel-services/ | L21: Kajabi website expert services | S21: kajabi course designer | X21: kajabi course design | Y21: Secondary Keyword | Z21: How do I organize my course materials effectively? | AD21: Why should I use a Kajabi course upload service? | AE21: Save time, ensure a polished, scalable course structure, proper tagging and sequencing, and fewer technical hiccups during launch | AF21: kajabi course upload services
C22: kajabi website​ | D22: 390 | E22: 820 | F22: 21 | G22: Navigational | H22: Primary Keyword | K22: https://theeduassist.com/blog/kajabi-online-course-setup/ | L22: sales pipelines and funnels | M22: Kajabi funnel setup | AD22: What files can you upload to Kajabi? | AE22: Videos (MP4), audio, PDFs, slides, quizzes, downloadable resources, and text content. We’ll format and organize them for best learner flow. | AF22: kajabi course upload services
C23: kajabi website expert​ | D23: 70 | E23: 70 | F23: 9 | G23: Commercial | H23: Secondary Keyword | K23: https://theeduassist.com/blog/discover-kajabi-the-most-popular-platform-of-elearning-world/ | L23: website creation | M23: Kajabi website setup | R23: kajabi membership site development | S23: kajabi membership site​ | T23: 70 | U23: 330 | V23: 23 | W23: Informational | X23: kajabi membership site development | Y23: Secondary Keyword | Z23: What is Kajabi, and why use it for a membership site? | AD23: How long does a typical Kajabi upload project take? | AE23: It depends on course length, but most projects range from 3–10 business days. Exact timeline is confirmed in a project brief. | AF23: kajabi course upload services
C24: kajabi sales funnel | D24: 20 | E24: 70 | G24: Informational | H24: Secondary Keyword | K24: https://theeduassist.com/blog/kajabi-course-design/ | L24: Kajabi funnels | M24: custom Kajabi website and funnel setup | S24: kajabi membership | T24: 20 | U24: 190 | W24: Informational | X24: kajabi membership site development | Y24: Secondary Keyword | Z24: How do I get started with building a membership site on Kajabi? | AD24: Can you set up quizzes, assignments, and certificates? | AE24: Absolutely. We configure quizzes, graded tasks, and completion certificates where Kajabi supports them. | AF24: kajabi course upload services
C25: best funnels to use on kajabi​ | G25: Informational | H25: Secondary Keyword | K25: https://theeduassist.com/blog/7-powerful-kajabi-course-creation-services/ | L25: Funnel setup | M25: Kajabi funnel setup services | S25: how to create a membership in kajabi | T25: 20 | U25: 30 | X25: kajabi membership site development | Y25: Secondary Keyword | Z25: Can I customize the look and feel of my Kajabi membership site? | AD25: Will you customize templates and pages for my course? | AE25: Yes. We tailor landing pages, sales pages, and course templates to match your branding and voice. | AF25: kajabi course upload services
C26: kajabi funnels​ | G26: Informational | H26: Secondary Keyword | S26: kajabi membership site examples​ | T26: 70 | U26: 150 | V26: 0 | W26: Informational | X26: kajabi membership site development | Y26: Secondary Keyword | Z26: How do I protect my content so only members can see it? | AD26: Can you optimize SEO and discoverability on Kajabi? | AE26: We optimize titles, descriptions, keywords, hero images, and meta data to improve search visibility inside and outside Kajabi. | AF26: kajabi course upload services
C27: best funnels to use on kajabi​ | G27: Informational | H27: Secondary Keyword | S27: how to cancel kajabi membership​ | T27: 20 | U27: 20 | X27: kajabi membership site development | Y27: Secondary Keyword | Z27: Do I need technical skills to create a membership site on Kajabi? | AD27: Do you handle revisions or edits after uploads? | AE27: Yes. Most services include a revision window. Additional edits may incur a small fee depending on scope. | AF27: kajabi course upload services
C28: Kajabi services | D28: 40 | E28: 70 | F28: 31 | G28: Navigational | S28: kajabi membership site development | X28: kajabi membership site development | Y28: Primary Keyword | Z28: Can I track how my membership is performing? | AD28: How do you protect my content and confidentiality? | AE28: Share a brief of your course assets and goals (video count, resources, pages). We’ll propose a plan, timeline, and quote, then begin after approval. | AF28: kajabi course upload services
B30: Kajabi Course Upload Service | C30: . | H30: Primary Keyword | I30: Professional Kajabi Course Upload Service | We Value Your Time | J30: Need your course live? Our professional Kajabi course upload service takes the stress away. We build it right the first time. Hire our experts here. | K30: https://theeduassist.com/blog/kajabi-online-course-setup/ | L30: Upload videos, add text, PDFs, audio files, or external embeds | M30: Kajabi Course Upload Services | R30: kajabi coaching program setup | S30: kajabi coaching program setup guide | X30: kajabi coaching program setup | Y30: Secondary Keyword | Z30: How Do I Set Up a Kajabi Coaching Program? | AA30: What are the 5 C's in coaching? | AD30: What are some best practices for Kajabi training? | AE30: Start with a clear product and pricing plan, use pipelines to bootstrap launches, automate welcome emails, segment your audience, and regularly update content based on student feedback. | AF30: kajabi training platform
C31: kajabi.services​ | H31: Secondary Keyword | K31: https://theeduassist.com/blog/7-powerful-kajabi-course-creation-services/ | L31: Course structure | M31: professional Kajabi course upload services | S31: kajabi coaching program setup for beginners | X31: kajabi coaching program setup | Y31: Secondary Keyword | Z31: How Long Does It Take to Set Up Kajabi Coaching? | AA31: What are the 3 C's of coaching? | AD31: What type of platform is Kajabi? | AE31: Kajabi was built as a business platform for knowledge entrepreneurs. Courses are one product type among several. On Kajabi, you also build your website, send email campaigns, create sales funnels, run a coaching practice, host a community, manage affiliates, and accept payments. | AF31: kajabi training platform
C32: Kajabi services | D32: 40 | E32: 70 | F32: 31 | G32: Navigational | H32: Secondary Keyword | K32: https://theeduassist.com/blog/kajabi-course-design-explained-how-to-create-online-course-in-2026/ | L32: upload your content | M32: upload your course to Kajabi | S32: kajabi coaching program | T32: 20 | U32: 40 | W32: Informational | X32: kajabi coaching program setup | Y32: Secondary Keyword | Z32: What Features Should My Kajabi Coaching Program Have? | AA32: What is the golden triangle of coaching? | AD32: Which is better, Kajabi or teachable? | AE32: Kajabi has more tools and product types. Teachable offers more courses per tier. Kajabi has more expensive plans, but it gives you access to extra products like podcasts in addition to multiple integrations and advanced email marketing tools. However, product numbers and customers are limited per tier. | AF32: kajabi training platform
C33: kajabi customer service | D33: 50 | E33: 140 | F33: 19 | G33: Informational | H33: Secondary Keyword | K33: https://theeduassist.com/blog/kajabi-course-design/ | L33: Kajabi content upload services | M33: Kajabi content upload services | N33: A well-designed course also requires proper implementation, which is why many creators use Kajabi content upload services to organize lessons and learning materials efficiently. | S33: kajabi coaching​ | T33: 30 | U33: 180 | V33: 12 | W33: Informational + navigational | X33: kajabi coaching program setup | Y33: Secondary Keyword | Z33: Can I Customize My Kajabi Coaching Program?
C34: kajabi help | D34: 110 | E34: 390 | F34: 20 | G34: Navigational+Commercial | H34: Secondary Keyword | K34: https://theeduassist.com/blog/kajabi-drip-course-setup/ | L34: Kajabi course content upload | M34: Kajabi course content upload | N34: Before configuring drip schedules, ensure your Kajabi course content upload process is completed correctly with structured modules and lesson assets. | S34: coaching kajabi​ | T34: 20 | U34: 50 | W34: Informational | X34: kajabi coaching program setup | Y34: Secondary Keyword | Z34: How to set up a coaching program? | AD34: Are there different types of templates in Kajabi? | AE34: Yes: course templates (structure), landing/page templates (for sales and branding), email sequence templates, and funnel/templates for onboarding. | AF34: kajabi course templates
C35: kajabi support | D35: 140 | E35: 490 | F35: 17 | G35: Navigational | H35: Secondary Keyword | S35: kajabi coaching platform​ | T35: 70 | U35: 100 | V35: 13 | W35: Informational + navigational | X35: kajabi coaching program setup | Y35: Secondary Keyword | Z35: What is the 70 30 rule in coaching? | AD35: Can I customize a Kajabi course template after applying it? | AE35: Absolutely. Templates are starting points and can be edited, renamed, reorganized, and re-styled to fit your brand | AF35: kajabi course templates
S36: kajabi coaching program setup | X36: kajabi coaching program setup | Y36: Primary Keyword | AD36: Can I import a template from another course? | AE36: Yes, you can clone or import course content from one product into another, which often includes templates as a base. | AF36: kajabi course templates
AD37: Do templates work with mobile and responsive design? | AE37: Yes, Kajabi templates are designed to be responsive, but you should still test on mobile devices. | AF37: kajabi course templates
R38: kajabi digital product creation | S38: kajabi digital products​ | T38: 20 | U38: 50 | X38: kajabi digital product creation | Y38: Secondary Keyword | Z38: What types of digital products can I create using Kajabi? | AD38: Can I use a template for a new niche or language? | AE38: Yes, templates are adaptable. You may need to update copy, media, and localization to fit your niche or language. | AF38: kajabi course templates
B39: Kajabi Migration Services | S39: kajabi digital products​ creation guide | X39: kajabi digital product creation | Y39: Secondary Keyword | Z39: Do I need any technical skills to create digital products on Kajabi? | AD39: How do I update or modify a template after launching? | AE39: You can edit the course pages, modules, and blocks anytime; changes apply to your live course without breaking students’ progress. | AF39: kajabi course templates
C40: Kajabi Migration | D40: 20 | E40: 60 | G40: Informational | H40: Secondary Keyword | I40: Move to Kajabi: Expert Migration for Your Growth | J40: Ready to move to Kajabi? Get a clean migration that saves you time. We move your courses and emails fast. Scale your business without the headaches. Call us. | K40: https://theeduassist.com/blog/kajabi-website-funnel-services/ | L40: Kajabi website migration | S40: kajabi digital products​ creation program | X40: kajabi digital product creation | Y40: Secondary Keyword | Z40: Can I sell my digital products on Kajabi? | AD40: What's the best way to choose a Kajabi template? | AE40: Consider your course goals, desired student flow, branding, and whether the template supports your media (video, downloads), assessments, and marketing pages. Test a sample to ensure it meets your needs. | AF40: kajabi course templates
C41: Kajabi Migration Services | H41: Primary Keyword | K41: https://theeduassist.com/blog/kajabi-online-course-setup/ | L41: migrate your course to Kajabi | M41: migrate your course to Kajabi | N41: If your course already exists on another platform, you can migrate your course to Kajabi while preserving your content structure, lessons, downloads, and learner experience. Add the above sentence. After this, Why Choose Kajabi for Your Online Course? | S41: how to sell digital products on kajabi | X41: kajabi digital product creation | Y41: Secondary Keyword | Z41: Is there customer support available if I encounter issues while creating products on Kajabi? | AD41: Are there limitations or downsides to using templates? | AE41: Templates can speed setup but may require reworking if your course structure is very unique; ensure the template fits your learning path. | AF41: kajabi course templates
C42: migrate from kajabi​ | D42: 10 | E42: 30 | H42: Secondary Keyword | K42: https://theeduassist.com/blog/discover-kajabi-the-most-popular-platform-of-elearning-world/ | L42: Kajabi migration experts | M42: Kajabi migration experts | N42: Kajabi vs Competitors section, Add. Many businesses work with Kajabi migration experts when moving from platforms like Thinkific, Teachable, or LearnWorlds to avoid data loss and technical issues. | S42: kajabi digital product setup | X42: kajabi digital product creation | Y42: Secondary Keyword
C43: migrate from kajabi to wordpress​ | H43: Secondary Keyword | K43: https://theeduassist.com/blog/7-powerful-kajabi-course-creation-services/ | L43: Kajabi course migration services | M43: Kajabi course migration services | N43: In the Kajabi course creation services section. Add, Many creators also require Kajabi course migration services when moving existing content from other learning platforms into Kajabi. | X43: kajabi digital product creation | Y43: Primary Keyword | AD43: What services are included in Kajabi Website & Funnel Services? | AE43: Website and landing page design, funnel planning, product and payment setup, email sequences, automation, lead magnets, SEO basics, and ongoing optimization. | AF43: Kajabi Website & Funnel Services
...

Sheet Kajabi Tree
B1: How to write an article : Pillar content should be at least 2000 words. Include every detail about topic. This page link to all it's cluster pages. Cluster content should to 800 to 1000 words. These content should be link to pilar content | K1: suggestion by Content wirtier | L1: Feedback | M1: Suggeestions by SEO | N1: Everyone Make sure to remove these preadded tags in the bottom of AISEO SEO settings and add your own title anddescription and focus words help improve the seo of the website
A2: Pillar Content | B2: Cluster Content | C2: Search Intent | D2: Suggested Title | E2: Suggested URL Slug | F2: keyword difficulty | G2: Description | H2: Written by | I2: Add Link here for linking | J2: new link | M2: Description incorrect.
A3: Kajabi Course Creation Services | D3: 7 Powerful Kajabi Course Creation Services That Skyrocket Sales | G3: Discover how Kajabi Course Creation Services help coaches and creators build stunning, high-converting online courses that boost engagement, sales, and growth. | H3: C2 | I3: https://theeduassist.com/blog/7-powerful-kajabi-course-creation-services-to-skyrocket-sales/ | K3: Rechecked and corrected. | M3: Description incorrect.
B4: kajabi online course setup | C4: transactional | D4: How to Set Up an Online Course on Kajabi | E4: kajabi-online-course-setup | F4: Medium | G4: Discover the ultimate Kajabi Online Course Setup guide to build, launch, and scale a high-converting course that boosts engagement, trust, and sales fast. | H4: C1 | I4: https://theeduassist.com/blog/kajabi-online-course-setup/ | K4: Rechecked and corrected.
B5: kajabi course design | C5: commercial | D5: Master Kajabi Course Design With These Simple steps | E5: kajabi-course-design | F5: Medium | G5: Master Kajabi Course Design with proven strategies to create stunning, engaging, and high-converting online courses that captivate learners and grow sales. | H5: C2 | I5: https://theeduassist.com/blog/kajabi-course-design/ | K5: Rechecked and corrected. | M5: Description incorrect.
B6: kajabi membership site development | C6: commercial | D6: What Are the Best Practices for Kajabi Membership Sites? | E6: kajabi-membership-site-development | F6: Medium | G6: Discover expert Kajabi membership site development services to create, manage, and grow your online community effortlessly. Start your journey today! | H6: C1 | I6: https://theeduassist.com/blog/kajabi-membership-sites-development/ | K6: Rechecked and corrected. | M6: Description incorrect.
B7: kajabi coaching program setup | C7: commercial | D7: Quick Tips for Setting Up Kajabi Coaching | E7: kajabi-coaching-program-setup | F7: Low | G7: Transform your ideas into income with our Kajabi coaching program setup. Get expert guidance to launch and grow your online business successfully! | H7: C2 | I7: https://theeduassist.com/blog/kajabi-coaching-program-setup/
B8: kajabi digital product creation | C8: informational | D8: How to Create Digital Products with Kajabi | E8: kajabi-digital-product-creation | F8: Low | G8: Ready to create and sell digital products? Kajabi offers everything you need to build, market, and grow your online business. Start your success story now! | H8: C1 | I8: https://theeduassist.com/blog/kajabi-digital-product-creation/
B9: kajabi drip course setup | C9: informational | D9: What Are the Best Practices for Kajabi Drip Courses? | E9: kajabi-drip-course-setup | F9: Low | G9: Discover how to set up a successful Kajabi drip course. Our expert tips will help you enhance user experience and maximize course engagement. | H9: C2 | I9: https://theeduassist.com/blog/kajabi-drip-course-setup/ | K9: Rechecked and corrected. | M9: Description incorrect.
B10: kajabi course upload services | C10: transactional | D10: 7 Common Mistakes In Kajabi Course Uploading To Avoid | E10: kajabi-course-upload-services | F10: Low | G10: Avoid these 7 common mistakes in Kajabi course uploading. Get your lessons right the first time for a better student experience. Click to learn more | H10: C1 | I10: https://theeduassist.com/uncategorized/kajabi-course-upload-services/ | K10: Rechecked and corrected. | L10: Rewrite it. Please Check. | M10: Description incorrect.
B11: kajabi training platform | C11: navigational | D11: how to create a training portal in kajabi | E11: kajabi-training-platform | F11: High | G11: Join our Kajabi training program and turn your passion into profit! Learn to create and market online courses with ease. Get started today! | H11: C4 | I11: https://theeduassist.com/blog/how-to-create-a-kajabi-training-platform/
B12: kajabi course templates | C12: informational | D12: Best Free and Paid Kajabi Course Templates & Themes for 2026 | E12: kajabi-course-templates | F12: Medium | G12: Find the ultimate collection of Kajabi course templates and themes for 2026. Boost your course's appeal with our curated selection of free and paid designs! | H12: C2 | I12: https://theeduassist.com/blog/kajabi-course-templates/
A14: Kajabi Website & Funnel Services | D14: Best Kajabi Funnel and Website Setup Services for 2026 Growth | G14: Boost your online presence with our Kajabi website and funnel services. We specialize in e-learning solutions to help you engage your audience effectively. | H14: C1 | I14: https://theeduassist.com/blog/kajabi-website-funnel-services/
B15: kajabi website design services | C15: commercial | D15: A Step-by-Step Guide to Finding the Best Kajabi Design Services | E15: kajabi-website-design-services | F15: High | G15: Hire the right Kajabi design services with these simple steps. We show you how to pick a designer who delivers results. Click to start now. | H15: C4 | I15: https://theeduassist.com/uncategorized/kajabi-website-design-services/
B16: kajabi sales funnel setup | C16: commercial | D16: The Future Of Sales Funnels: Leveraging Kajabi For Growth | E16: kajabi-sales-funnel-setup | F16: Medium | G16: Use Kajabi to build smart sales funnels that actually work. Stop losing leads and start making more sales. See how to grow your brand now. | H16: C2 | I16: https://theeduassist.com/blog/kajabi-sales-funnel-setup/
B17: kajabi landing page design | C17: commercial | D17: How to Optimize Your Kajabi Landing Page for Conversions | E17: kajabi-landing-page-design | F17: Medium | G17: Turn your visitors into buyers. We show you how to optimize your Kajabi landing page for conversions quickly. Boost your ROI with these proven steps. | H17: C1 | I17: https://theeduassist.com/blog/kajabi-landing-page-design/
